Workbook

Sheet PER
BK32: =CONCATENATE("OBLIGATORIEDAD DE (",BK33,")") -> OBLIGATORIEDAD DE (Set up)
V33: NECESIDADES | W33: 16h | X33: 17h | Y33: 18h | Z33: 19h | AA33: 20h | AB33: 21h | AC33: 22h | AD33: 23h | AE33: 00h | AF33: 01h | AG33: 02h | AH33: 03h | AI33: 04h | AJ33: 05h | AK33: 06h | AL33: 07h | AM33: 08h | AN33: TOTAL / TAREA | AR33: =$W$33 -> 16h | AS33: =$X$33 -> 17h | AT33: =$Y$33 -> 18h | AU33: =$Z$33 -> 19h | AV33: =$AA$33 -> 20h | AW33: =$AB$33 -> 21h | AX33: =$AC$33 -> 22h | AY33: =$AD$33 -> 23h | AZ33: =$AE$33 -> 00h | BA33: =$AF$33 -> 01h | BB33: =$AG$33 -> 02h | BC33: =$AH$33 -> 03h | BD33: =$AI$33 -> 04h | BE33: =$AJ$33 -> 05h | BF33: =$AK$33 -> 06h | BG33: =$AL$33 -> 07h | BH33: =$AM$33 -> 08h | BK33: =V34 -> Set up | BL33: =$W$33 -> 16h | BM33: =$X$33 -> 17h | BN33: =$Y$33 -> 18h | BO33: =$Z$33 -> 19h | BP33: =$AA$33 -> 20h | BQ33: =$AB$33 -> 21h | BR33: =$AC$33 -> 22h | BS33: =$AD$33 -> 23h | BT33: =$AE$33 -> 00h | BU33: =$AF$33 -> 01h | BV33: =$AG$33 -> 02h | BW33: =$AH$33 -> 03h | BX33: =$AI$33 -> 04h | BY33: =$AJ$33 -> 05h | BZ33: =$AK$33 -> 06h | CA33: =$AL$33 -> 07h | CB33: =$AM$33 -> 08h
R34: max | S34: 12 | U34: 1 | V34: Set up | W34: 1 | X34: 1 | Y34: 1 | Z34: 1 | AA34: 1 | AB34: 1 | AC34: 1 | AD34: 1 | AE34: 1 | AF34: 1 | AG34: 1 | AH34: 1 | AI34: 0 | AJ34: 0 | AK34: 0 | AL34: 0 | AM34: 0 | AN34: =SUM(W34:AM34) -> 12 | AP34: =$V$34 -> Set up | AQ34: =$V$53 -> Jennifer | AR34: 0 | AS34: 1 | AT34: 0 | AU34: 0 | AV34: 1 | AW34: 0 | AX34: 1 | AY34: 0 | AZ34: 0 | BA34: 1 | BB34: 0 | BC34: 0 | BD34: 0 | BE34: 0 | BF34: 0 | BG34: 0 | BH34: 0 | BK34: =$V$53 -> Jennifer | BL34: 0 | BM34: 0 | BN34: 0 | BO34: 0 | BP34: 0 | BQ34: 0 | BR34: 0 | BS34: 0 | BT34: 0 | BU34: 0 | BV34: 0 | BW34: 0 | BX34: 0 | BY34: 0 | BZ34: 0 | CA34: 0 | CB34: 0
R35: min | S35: -8 | U35: 2 | V35: Entry | W35: 1 | X35: 1 | Y35: 1 | Z35: 1 | AA35: 1 | AB35: 1 | AC35: 1 | AD35: 1 | AE35: 1 | AF35: 1 | AG35: 1 | AH35: 1 | AI35: 0 | AJ35: 0 | AK35: 0 | AL35: 0 | AM35: 0 | AN35: =SUM(W35:AM35) -> 12 | AQ35: =$V$54 -> Galileo | AR35: 0 | AS35: 0 | AT35: 0 | AU35: 0 | AV35: 0 | AW35: 0 | AX35: 0 | AY35: 0 | AZ35: 1 | BA35: 0 | BB35: 0 | BC35: 0 | BD35: 0 | BE35: 0 | BF35: 0 | BG35: 0 | BH35: 0 | BK35: =$V$54 -> Galileo | BL35: 0 | BM35: 0 | BN35: 0 | BO35: 0 | BP35: 0 | BQ35: 0 | BR35: 0 | BS35: 0 | BT35: 0 | BU35: 0 | BV35: 0 | BW35: 0 | BX35: 0 | BY35: 0 | BZ35: 0 | CA35: 0 | CB35: 0
U36: 3 | V36: Bar | W36: 1 | X36: 1 | Y36: 1 | Z36: 1 | AA36: 1 | AB36: 1 | AC36: 1 | AD36: 1 | AE36: 1 | AF36: 1 | AG36: 1 | AH36: 1 | AI36: 0 | AJ36: 0 | AK36: 0 | AL36: 0 | AM36: 0 | AN36: =SUM(W36:AM36) -> 12 | AQ36: =$V$55 -> Óscar | AR36: 0 | AS36: 0 | AT36: 0 | AU36: 0 | AV36: 0 | AW36: 0 | AX36: 0 | AY36: 0 | AZ36: 0 | BA36: 0 | BB36: 1 | BC36: 0 | BD36: 0 | BE36: 0 | BF36: 0 | BG36: 0 | BH36: 0 | BK36: =$V$55 -> Óscar | BL36: 0 | BM36: 0 | BN36: 0 | BO36: 0 | BP36: 0 | BQ36: 0 | BR36: 0 | BS36: 0 | BT36: 0 | BU36: 0 | BV36: 0 | BW36: 0 | BX36: 0 | BY36: 0 | BZ36: 0 | CA36: 0 | CB36: 0
R37: obj | S37: =100*(S34-S35)+10*SUM(D53:S92)+10*SUM(C99:S138) -> 2000 | U37: 4 | V37: C-mix | W37: 1 | X37: 1 | Y37: 1 | Z37: 1 | AA37: 1 | AB37: 1 | AC37: 1 | AD37: 1 | AE37: 1 | AF37: 1 | AG37: 1 | AH37: 1 | AI37: 0 | AJ37: 0 | AK37: 0 | AL37: 0 | AM37: 0 | AN37: =SUM(W37:AM37) -> 12 | AQ37: =$V$56 -> Sebastián | AR37: 0 | AS37: 0 | AT37: 0 | AU37: 0 | AV37: 0 | AW37: 0 | AX37: 0 | AY37: 0 | AZ37: 0 | BA37: 0 | BB37: 0 | BC37: 0 | BD37: 0 | BE37: 0 | BF37: 0 | BG37: 0 | BH37: 0 | BK37: =$V$56 -> Sebastián | BL37: 0 | BM37: 0 | BN37: 0 | BO37: 0 | BP37: 0 | BQ37: 0 | BR37: 0 | BS37: 0 | BT37: 0 | BU37: 0 | BV37: 0 | BW37: 0 | BX37: 0 | BY37: 0 | BZ37: 0 | CA37: 0 | CB37: 0
U38: 5 | V38: Rez | W38: 1 | X38: 1 | Y38: 1 | Z38: 1 | AA38: 1 | AB38: 1 | AC38: 1 | AD38: 1 | AE38: 1 | AF38: 1 | AG38: 1 | AH38: 1 | AI38: 0 | AJ38: 0 | AK38: 0 | AL38: 0 | AM38: 0 | AN38: =SUM(W38:AM38) -> 12 | AQ38: =$V$57 -> Marcos | AR38: 0 | AS38: 0 | AT38: 0 | AU38: 0 | AV38: 0 | AW38: 0 | AX38: 0 | AY38: 1 | AZ38: 0 | BA38: 0 | BB38: 0 | BC38: 0 | BD38: 0 | BE38: 0 | BF38: 0 | BG38: 0 | BH38: 0 | BK38: =$V$57 -> Marcos | BL38: 0 | BM38: 0 | BN38: 0 | BO38: 0 | BP38: 0 | BQ38: 0 | BR38: 0 | BS38: 0 | BT38: 0 | BU38: 0 | BV38: 0 | BW38: 0 | BX38: 0 | BY38: 0 | BZ38: 0 | CA38: 0 | CB38: 0
U39: 6 | V39: Homing | W39: 0 | X39: 0 | Y39: 0 | Z39: 0 | AA39: 0 | AB39: 0 | AC39: 0 | AD39: 0 | AE39: 0 | AF39: 0 | AG39: 0 | AH39: 0 | AI39: 0 | AJ39: 0 | AK39: 0 | AL39: 0 | AM39: 0 | AN39: =SUM(W39:AM39) -> 0 | AQ39: =$V$58 -> Weixin | AR39: 0 | AS39: 0 | AT39: 0 | AU39: 1 | AV39: 0 | AW39: 0 | AX39: 0 | AY39: 0 | AZ39: 0 | BA39: 0 | BB39: 0 | BC39: 0 | BD39: 0 | BE39: 0 | BF39: 0 | BG39: 0 | BH39: 0 | BK39: =$V$58 -> Weixin | BL39: 0 | BM39: 0 | BN39: 0 | BO39: 0 | BP39: 0 | BQ39: 0 | BR39: 0 | BS39: 0 | BT39: 0 | BU39: 0 | BV39: 0 | BW39: 0 | BX39: 0 | BY39: 0 | BZ39: 0 | CA39: 0 | CB39: 0
U40: 7 | V40: Toilets | W40: 0 | X40: 0 | Y40: 0 | Z40: 0 | AA40: 0 | AB40: 0 | AC40: 0 | AD40: 0 | AE40: 0 | AF40: 0 | AG40: 0 | AH40: 0 | AI40: 0 | AJ40: 0 | AK40: 0 | AL40: 0 | AM40: 0 | AN40: =SUM(W40:AM40) -> 0 | AQ40: =$V$59 -> Benjamin | AR40: 1 | AS40: 0 | AT40: 1 | AU40: 0 | AV40: 0 | AW40: 1 | AX40: 0 | AY40: 0 | AZ40: 0 | BA40: 0 | BB40: 0 | BC40: 1 | BD40: 0 | BE40: 0 | BF40: 0 | BG40: 0 | BH40: 0 | BK40: =$V$59 -> Benjamin | BL40: 0 | BM40: 0 | BN40: 0 | BO40: 0 | BP40: 0 | BQ40: 0 | BR40: 0 | BS40: 0 | BT40: 0 | BU40: 0 | BV40: 0 | BW40: 0 | BX40: 0 | BY40: 0 | BZ40: 0 | CA40: 0 | CB40: 0
U41: 8 | V41: Level | W41: 0 | X41: 0 | Y41: 0 | Z41: 0 | AA41: 0 | AB41: 0 | AC41: 0 | AD41: 0 | AE41: 0 | AF41: 0 | AG41: 0 | AH41: 0 | AI41: 0 | AJ41: 0 | AK41: 0 | AL41: 0 | AM41: 0 | AN41: =SUM(W41:AM41) -> 0 | AQ41: =$V$60 -> Joelle | AR41: 0 | AS41: 0 | AT41: 0 | AU41: 0 | AV41: 0 | AW41: 0 | AX41: 0 | AY41: 0 | AZ41: 0 | BA41: 0 | BB41: 0 | BC41: 0 | BD41: 0 | BE41: 0 | BF41: 0 | BG41: 0 | BH41: 0 | BK41: =$V$60 -> Joelle | BL41: 0 | BM41: 0 | BN41: 0 | BO41: 0 | BP41: 0 | BQ41: 0 | BR41: 0 | BS41: 0 | BT41: 0 | BU41: 0 | BV41: 0 | BW41: 0 | BX41: 0 | BY41: 0 | BZ41: 0 | CA41: 0 | CB41: 0
U42: 9 | V42: Çapèse | W42: 0 | X42: 0 | Y42: 0 | Z42: 0 | AA42: 0 | AB42: 0 | AC42: 0 | AD42: 0 | AE42: 0 | AF42: 0 | AG42: 0 | AH42: 0 | AI42: 0 | AJ42: 0 | AK42: 0 | AL42: 0 | AM42: 0 | AN42: =SUM(W42:AM42) -> 0 | AQ42: =$V$61 -> Alexia | AR42: 0 | AS42: 0 | AT42: 0 | AU42: 0 | AV42: 0 | AW42: 0 | AX42: 0 | AY42: 0 | AZ42: 0 | BA42: 0 | BB42: 0 | BC42: 0 | BD42: 0 | BE42: 0 | BF42: 0 | BG42: 0 | BH42: 0 | BK42: =$V$61 -> Alexia | BL42: 0 | BM42: 0 | BN42: 0 | BO42: 0 | BP42: 0 | BQ42: 0 | BR42: 0 | BS42: 0 | BT42: 0 | BU42: 0 | BV42: 0 | BW42: 0 | BX42: 0 | BY42: 0 | BZ42: 0 | CA42: 0 | CB42: 0
U43: 10 | V43: Tidying | W43: 0 | X43: 0 | Y43: 0 | Z43: 0 | AA43: 0 | AB43: 0 | AC43: 0 | AD43: 0 | AE43: 0 | AF43: 0 | AG43: 0 | AH43: 0 | AI43: 0 | AJ43: 0 | AK43: 0 | AL43: 0 | AM43: 0 | AN43: =SUM(W43:AM43) -> 0 | AQ43: =$V$62 -> Joao | AR43: 0 | AS43: 0 | AT43: 0 | AU43: 0 | AV43: 0 | AW43: 0 | AX43: 0 | AY43: 0 | AZ43: 0 | BA43: 0 | BB43: 0 | BC43: 0 | BD43: 0 | BE43: 0 | BF43: 0 | BG43: 0 | BH43: 0 | BK43: =$V$62 -> Joao | BL43: 0 | BM43: 0 | BN43: 0 | BO43: 0 | BP43: 0 | BQ43: 0 | BR43: 0 | BS43: 0 | BT43: 0 | BU43: 0 | BV43: 0 | BW43: 0 | BX43: 0 | BY43: 0 | BZ43: 0 | CA43: 0 | CB43: 0
U44: 11 | V44: Volante | W44: 0 | X44: 0 | Y44: 0 | Z44: 0 | AA44: 0 | AB44: 0 | AC44: 0 | AD44: 0 | AE44: 0 | AF44: 0 | AG44: 0 | AH44: 0 | AI44: 0 | AJ44: 0 | AK44: 0 | AL44: 0 | AM44: 0 | AN44: =SUM(W44:AM44) -> 0 | AQ44: =$V$63 -> Maxime | AR44: 0 | AS44: 0 | AT44: 0 | AU44: 0 | AV44: 0 | AW44: 0 | AX44: 0 | AY44: 0 | AZ44: 0 | BA44: 0 | BB44: 0 | BC44: 0 | BD44: 0 | BE44: 0 | BF44: 0 | BG44: 0 | BH44: 0 | BK44: =$V$63 -> Maxime | BL44: 0 | BM44: 0 | BN44: 0 | BO44: 0 | BP44: 0 | BQ44: 0 | BR44: 0 | BS44: 1 | BT44: 0 | BU44: 0 | BV44: 0 | BW44: 0 | BX44: 0 | BY44: 0 | BZ44: 0 | CA44: 0 | CB44: 0
U45: 12 | V45: Dummy 1 | W45: 0 | X45: 0 | Y45: 0 | Z45: 0 | AA45: 0 | AB45: 0 | AC45: 0 | AD45: 0 | AE45: 0 | AF45: 0 | AG45: 0 | AH45: 0 | AI45: 0 | AJ45: 0 | AK45: 0 | AL45: 0 | AM45: 0 | AN45: =SUM(W45:AM45) -> 0 | AQ45: =$V$64 -> Alex | AR45: 0 | AS45: 0 | AT45: 0 | AU45: 0 | AV45: 0 | AW45: 0 | AX45: 0 | AY45: 0 | AZ45: 0 | BA45: 0 | BB45: 0 | BC45: 0 | BD45: 0 | BE45: 0 | BF45: 0 | BG45: 0 | BH45: 0 | BK45: =$V$64 -> Alex | BL45: 0 | BM45: 0 | BN45: 0 | BO45: 0 | BP45: 0 | BQ45: 0 | BR45: 0 | BS45: 0 | BT45: 1 | BU45: 0 | BV45: 0 | BW45: 0 | BX45: 0 | BY45: 0 | BZ45: 0 | CA45: 0 | CB45: 0
U46: 13 | V46: Dummy 2 | W46: 0 | X46: 0 | Y46: 0 | Z46: 0 | AA46: 0 | AB46: 0 | AC46: 0 | AD46: 0 | AE46: 0 | AF46: 0 | AG46: 0 | AH46: 0 | AI46: 0 | AJ46: 0 | AK46: 0 | AL46: 0 | AM46: 0 | AN46: =SUM(W46:AM46) -> 0 | AQ46: =$V$65 -> Alyssa | AR46: 0 | AS46: 0 | AT46: 0 | AU46: 0 | AV46: 0 | AW46: 0 | AX46: 0 | AY46: 0 | AZ46: 0 | BA46: 0 | BB46: 0 | BC46: 0 | BD46: 0 | BE46: 0 | BF46: 0 | BG46: 0 | BH46: 0 | BK46: =$V$65 -> Alyssa | BL46: 0 | BM46: 0 | BN46: 0 | BO46: 0 | BP46: 0 | BQ46: 0 | BR46: 0 | BS46: 0 | BT46: 0 | BU46: 0 | BV46: 0 | BW46: 0 | BX46: 0 | BY46: 0 | BZ46: 0 | CA46: 0 | CB46: 0
U47: 14 | V47: Dummy 3 | W47: 0 | X47: 0 | Y47: 0 | Z47: 0 | AA47: 0 | AB47: 0 | AC47: 0 | AD47: 0 | AE47: 0 | AF47: 0 | AG47: 0 | AH47: 0 | AI47: 0 | AJ47: 0 | AK47: 0 | AL47: 0 | AM47: 0 | AN47: =SUM(W47:AM47) -> 0 | AQ47: =$V$66 -> Amanda | AR47: 0 | AS47: 0 | AT47: 0 | AU47: 0 | AV47: 0 | AW47: 0 | AX47: 0 | AY47: 0 | AZ47: 0 | BA47: 0 | BB47: 0 | BC47: 0 | BD47: 0 | BE47: 0 | BF47: 0 | BG47: 0 | BH47: 0 | BK47: =$V$66 -> Amanda | BL47: 0 | BM47: 0 | BN47: 0 | BO47: 0 | BP47: 0 | BQ47: 0 | BR47: 0 | BS47: 0 | BT47: 0 | BU47: 0 | BV47: 0 | BW47: 0 | BX47: 0 | BY47: 0 | BZ47: 0 | CA47: 0 | CB47: 0
U48: 15 | V48: Dummy 4 | W48: 0 | X48: 0 | Y48: 0 | Z48: 0 | AA48: 0 | AB48: 0 | AC48: 0 | AD48: 0 | AE48: 0 | AF48: 0 | AG48: 0 | AH48: 0 | AI48: 0 | AJ48: 0 | AK48: 0 | AL48: 0 | AM48: 0 | AN48: =SUM(W48:AM48) -> 0 | AQ48: =$V$67 -> Antoine | AR48: 0 | AS48: 0 | AT48: 0 | AU48: 0 | AV48: 0 | AW48: 0 | AX48: 0 | AY48: 0 | AZ48: 0 | BA48: 0 | BB48: 0 | BC48: 0 | BD48: 0 | BE48: 0 | BF48: 0 | BG48: 0 | BH48: 0 | BK48: =$V$67 -> Antoine | BL48: 0 | BM48: 0 | BN48: 0 | BO48: 0 | BP48: 0 | BQ48: 0 | BR48: 0 | BS48: 0 | BT48: 0 | BU48: 0 | BV48: 0 | BW48: 0 | BX48: 0 | BY48: 0 | BZ48: 0 | CA48: 0 | CB48: 0
AQ49: =$V$68 -> Beatriz | AR49: 0 | AS49: 0 | AT49: 0 | AU49: 0 | AV49: 0 | AW49: 0 | AX49: 0 | AY49: 0 | AZ49: 0 | BA49: 0 | BB49: 0 | BC49: 0 | BD49: 0 | BE49: 0 | BF49: 0 | BG49: 0 | BH49: 0 | BK49: =$V$68 -> Beatriz | BL49: 0 | BM49: 0 | BN49: 0 | BO49: 0 | BP49: 0 | BQ49: 0 | BR49: 0 | BS49: 0 | BT49: 0 | BU49: 0 | BV49: 0 | BW49: 0 | BX49: 0 | BY49: 0 | BZ49: 0 | CA49: 0 | CB49: 0
AQ50: =$V$69 -> Charelle | AR50: 0 | AS50: 0 | AT50: 0 | AU50: 0 | AV50: 0 | AW50: 0 | AX50: 0 | AY50: 0 | AZ50: 0 | BA50: 0 | BB50: 0 | BC50: 0 | BD50: 0 | BE50: 0 | BF50: 0 | BG50: 0 | BH50: 0 | BK50: =$V$69 -> Charelle | BL50: 0 | BM50: 0 | BN50: 0 | BO50: 0 | BP50: 0 | BQ50: 0 | BR50: 0 | BS50: 0 | BT50: 0 | BU50: 0 | BV50: 0 | BW50: 0 | BX50: 0 | BY50: 0 | BZ50: 0 | CA50: 0 | CB50: 0
C51: variables binarias para no consecutividad de tareas | AQ51: =$V$70 -> Dimitri | AR51: 0 | AS51: 0 | AT51: 0 | AU51: 0 | AV51: 0 | AW51: 0 | AX51: 0 | AY51: 0 | AZ51: 0 | BA51: 0 | BB51: 0 | BC51: 0 | BD51: 0 | BE51: 0 | BF51: 0 | BG51: 0 | BH51: 0 | BK51: =$V$70 -> Dimitri | BL51: 0 | BM51: 0 | BN51: 0 | BO51: 0 | BP51: 0 | BQ51: 0 | BR51: 0 | BS51: 0 | BT51: 0 | BU51: 0 | BV51: 0 | BW51: 0 | BX51: 0 | BY51: 0 | BZ51: 0 | CA51: 0 | CB51: 0
C52: CONSECUTIVIDAD | D52: =$W$33 -> 16h | E52: =$X$33 -> 17h | F52: =$Y$33 -> 18h | G52: =$Z$33 -> 19h | H52: =$AA$33 -> 20h | I52: =$AB$33 -> 21h | J52: =$AC$33 -> 22h | K52: =$AD$33 -> 23h | L52: =$AE$33 -> 00h | M52: =$AF$33 -> 01h | N52: =$AG$33 -> 02h | O52: =$AH$33 -> 03h | P52: =$AI$33 -> 04h | Q52: =$AJ$33 -> 05h | R52: =$AK$33 -> 06h | S52: =$AL$33 -> 07h | V52: DISPONIBILIDAD | W52: =$W$33 -> 16h | X52: =$X$33 -> 17h | Y52: =$Y$33 -> 18h | Z52: =$Z$33 -> 19h | AA52: =$AA$33 -> 20h | AB52: =$AB$33 -> 21h | AC52: =$AC$33 -> 22h | AD52: =$AD$33 -> 23h | AE52: =$AE$33 -> 00h | AF52: =$AF$33 -> 01h | AG52: =$AG$33 -> 02h | AH52: =$AH$33 -> 03h | AI52: =$AI$33 -> 04h | AJ52: =$AJ$33 -> 05h | AK52: =$AK$33 -> 06h | AL52: =$AL$33 -> 07h | AM52: =$AM$33 -> 08h | AN52: TOTAL / PERSONA | AQ52: =$V$71 -> Marina | AR52: 0 | AS52: 0 | AT52: 0 | AU52: 0 | AV52: 0 | AW52: 0 | AX52: 0 | AY52: 0 | AZ52: 0 | BA52: 0 | BB52: 0 | BC52: 0 | BD52: 0 | BE52: 0 | BF52: 0 | BG52: 0 | BH52: 0 | BK52: =$V$71 -> Marina | BL52: 0 | BM52: 0 | BN52: 0 | BO52: 0 | BP52: 0 | BQ52: 0 | BR52: 0 | BS52: 0 | BT52: 0 | BU52: 0 | BV52: 0 | BW52: 0 | BX52: 0 | BY52: 0 | BZ52: 0 | CA52: 0 | CB52: 0
C53: =$V$53 -> Jennifer | D53: 0 | E53: 0 | F53: 0 | G53: 0 | H53: 0 | I53: 0 | J53: 0 | K53: 0 | L53: 0 | M53: 0 | N53: 0 | O53: 0 | P53: 0 | Q53: 0 | R53: 0 | S53: 0 | U53: 1 | V53: Jennifer | W53: 1 | X53: 1 | Y53: 1 | Z53: 1 | AA53: 1 | AB53: 1 | AC53: 1 | AD53: 1 | AE53: 1 | AF53: 1 | AG53: 1 | AH53: 1 | AI53: 0 | AJ53: 0 | AK53: 0 | AL53: 0 | AM53: 0 | AN53: =SUM(W53:AM53) -> 12 | AQ53: =$V$72 -> Michel | AR53: 0 | AS53: 0 | AT53: 0 | AU53: 0 | AV53: 0 | AW53: 0 | AX53: 0 | AY53: 0 | AZ53: 0 | BA53: 0 | BB53: 0 | BC53: 0 | BD53: 0 | BE53: 0 | BF53: 0 | BG53: 0 | BH53: 0 | BK53: =$V$72 -> Michel | BL53: 0 | BM53: 0 | BN53: 0 | BO53: 0 | BP53: 0 | BQ53: 0 | BR53: 0 | BS53: 0 | BT53: 0 | BU53: 0 | BV53: 0 | BW53: 0 | BX53: 0 | BY53: 0 | BZ53: 0 | CA53: 0 | CB53: 0
C54: =$V$54 -> Galileo | D54: 0 | E54: 0 | F54: 0 | G54: 0 | H54: 0 | I54: 0 | J54: 0 | K54: 0 | L54: 0 | M54: 0 | N54: 0 | O54: 0 | P54: 0 | Q54: 0 | R54: 0 | S54: 0 | U54: 2 | V54: Galileo | W54: 1 | X54: 1 | Y54: 1 | Z54: 1 | AA54: 1 | AB54: 1 | AC54: 1 | AD54: 1 | AE54: 1 | AF54: 1 | AG54: 1 | AH54: 1 | AI54: 0 | AJ54: 0 | AK54: 0 | AL54: 0 | AM54: 0 | AN54: =SUM(W54:AM54) -> 12 | AQ54: =$V$73 -> Nour | AR54: 0 | AS54: 0 | AT54: 0 | AU54: 0 | AV54: 0 | AW54: 0 | AX54: 0 | AY54: 0 | AZ54: 0 | BA54: 0 | BB54: 0 | BC54: 0 | BD54: 0 | BE54: 0 | BF54: 0 | BG54: 0 | BH54: 0 | BK54: =$V$73 -> Nour | BL54: 0 | BM54: 0 | BN54: 0 | BO54: 0 | BP54: 0 | BQ54: 0 | BR54: 0 | BS54: 0 | BT54: 0 | BU54: 0 | BV54: 0 | BW54: 0 | BX54: 0 | BY54: 0 | BZ54: 0 | CA54: 0 | CB54: 0
C55: =$V$55 -> Óscar | D55: 0 | E55: 0 | F55: 0 | G55: 0 | H55: 0 | I55: 0 | J55: 0 | K55: 0 | L55: 0 | M55: 0 | N55: 0 | O55: 0 | P55: 0 | Q55: 0 | R55: 0 | S55: 0 | U55: 3 | V55: Óscar | W55: 1 | X55: 1 | Y55: 1 | Z55: 1 | AA55: 1 | AB55: 1 | AC55: 1 | AD55: 1 | AE55: 1 | AF55: 1 | AG55: 1 | AH55: 1 | AI55: 0 | AJ55: 0 | AK55: 0 | AL55: 0 | AM55: 0 | AN55: =SUM(W55:AM55) -> 12 | AQ55: =$V$74 -> Samuel | AR55: 0 | AS55: 0 | AT55: 0 | AU55: 0 | AV55: 0 | AW55: 0 | AX55: 0 | AY55: 0 | AZ55: 0 | BA55: 0 | BB55: 0 | BC55: 0 | BD55: 0 | BE55: 0 | BF55: 0 | BG55: 0 | BH55: 0 | BK55: =$V$74 -> Samuel | BL55: 0 | BM55: 0 | BN55: 0 | BO55: 0 | BP55: 0 | BQ55: 0 | BR55: 0 | BS55: 0 | BT55: 0 | BU55: 0 | BV55: 0 | BW55: 0 | BX55: 0 | BY55: 0 | BZ55: 0 | CA55: 0 | CB55: 0
C56: =$V$56 -> Sebastián | D56: 0 | E56: 0 | F56: 0 | G56: 0 | H56: 0 | I56: 0 | J56: 0 | K56: 0 | L56: 0 | M56: 0 | N56: 0 | O56: 0 | P56: 0 | Q56: 0 | R56: 0 | S56: 0 | U56: 4 | V56: Sebastián | W56: 1 | X56: 1 | Y56: 1 | Z56: 1 | AA56: 1 | AB56: 1 | AC56: 1 | AD56: 1 | AE56: 1 | AF56: 1 | AG56: 1 | AH56: 1 | AI56: 0 | AJ56: 0 | AK56: 0 | AL56: 0 | AM56: 0 | AN56: =SUM(W56:AM56) -> 12 | AQ56: =$V$75 -> Yassin | AR56: 0 | AS56: 0 | AT56: 0 | AU56: 0 | AV56: 0 | AW56: 0 | AX56: 0 | AY56: 0 | AZ56: 0 | BA56: 0 | BB56: 0 | BC56: 0 | BD56: 0 | BE56: 0 | BF56: 0 | BG56: 0 | BH56: 0 | BK56: =$V$75 -> Yassin | BL56: 0 | BM56: 0 | BN56: 0 | BO56: 0 | BP56: 0 | BQ56: 0 | BR56: 0 | BS56: 0 | BT56: 0 | BU56: 0 | BV56: 0 | BW56: 0 | BX56: 0 | BY56: 0 | BZ56: 0 | CA56: 0 | CB56: 0
C57: =$V$57 -> Marcos | D57: 0 | E57: 0 | F57: 0 | G57: 0 | H57: 0 | I57: 0 | J57: 0 | K57: 0 | L57: 0 | M57: 0 | N57: 0 | O57: 0 | P57: 0 | Q57: 0 | R57: 0 | S57: 0 | U57: 5 | V57: Marcos | W57: 1 | X57: 1 | Y57: 1 | Z57: 1 | AA57: 1 | AB57: 1 | AC57: 1 | AD57: 1 | AE57: 1 | AF57: 1 | AG57: 1 | AH57: 1 | AI57: 0 | AJ57: 0 | AK57: 0 | AL57: 0 | AM57: 0 | AN57: =SUM(W57:AM57) -> 12 | AQ57: =$V$76 -> Kamar | AR57: 0 | AS57: 0 | AT57: 0 | AU57: 0 | AV57: 0 | AW57: 0 | AX57: 0 | AY57: 0 | AZ57: 0 | BA57: 0 | BB57: 0 | BC57: 0 | BD57: 0 | BE57: 0 | BF57: 0 | BG57: 0 | BH57: 0 | BK57: =$V$76 -> Kamar | BL57: 0 | BM57: 0 | BN57: 0 | BO57: 0 | BP57: 0 | BQ57: 0 | BR57: 0 | BS57: 0 | BT57: 0 | BU57: 0 | BV57: 0 | BW57: 0 | BX57: 0 | BY57: 0 | BZ57: 0 | CA57: 0 | CB57: 0
C58: =$V$58 -> Weixin | D58: 0 | E58: 0 | F58: 0 | G58: 0 | H58: 0 | I58: 0 | J58: 0 | K58: 0 | L58: 0 | M58: 0 | N58: 0 | O58: 0 | P58: 0 | Q58: 0 | R58: 0 | S58: 0 | U58: 6 | V58: Weixin | W58: 1 | X58: 1 | Y58: 1 | Z58: 1 | AA58: 1 | AB58: 1 | AC58: 1 | AD58: 1 | AE58: 1 | AF58: 1 | AG58: 1 | AH58: 1 | AI58: 0 | AJ58: 0 | AK58: 0 | AL58: 0 | AM58: 0 | AN58: =SUM(W58:AM58) -> 12 | AQ58: =$V$77 -> - | AR58: 0 | AS58: 0 | AT58: 0 | AU58: 0 | AV58: 0 | AW58: 0 | AX58: 0 | AY58: 0 | AZ58: 0 | BA58: 0 | BB58: 0 | BC58: 0 | BD58: 0 | BE58: 0 | BF58: 0 | BG58: 0 | BH58: 0 | BK58: =$V$77 -> - | BL58: 0 | BM58: 0 | BN58: 0 | BO58: 0 | BP58: 0 | BQ58: 0 | BR58: 0 | BS58: 0 | BT58: 0 | BU58: 0 | BV58: 0 | BW58: 0 | BX58: 0 | BY58: 0 | BZ58: 0 | CA58: 0 | CB58: 0
C59: =$V$59 -> Benjamin | D59: 0 | E59: 0 | F59: 0 | G59: 0 | H59: 0 | I59: 0 | J59: 0 | K59: 0 | L59: 0 | M59: 0 | N59: 0 | O59: 0 | P59: 0 | Q59: 0 | R59: 0 | S59: 0 | U59: 7 | V59: Benjamin | W59: 1 | X59: 1 | Y59: 1 | Z59: 1 | AA59: 1 | AB59: 1 | AC59: 1 | AD59: 1 | AE59: 1 | AF59: 1 | AG59: 1 | AH59: 1 | AI59: 0 | AJ59: 0 | AK59: 0 | AL59: 0 | AM59: 0 | AN59: =SUM(W59:AM59) -> 12 | AQ59: =$V$78 -> - | AR59: 0 | AS59: 0 | AT59: 0 | AU59: 0 | AV59: 0 | AW59: 0 | AX59: 0 | AY59: 0 | AZ59: 0 | BA59: 0 | BB59: 0 | BC59: 0 | BD59: 0 | BE59: 0 | BF59: 0 | BG59: 0 | BH59: 0 | BK59: =$V$78 -> - | BL59: 0 | BM59: 0 | BN59: 0 | BO59: 0 | BP59: 0 | BQ59: 0 | BR59: 0 | BS59: 0 | BT59: 0 | BU59: 0 | BV59: 0 | BW59: 0 | BX59: 0 | BY59: 0 | BZ59: 0 | CA59: 0 | CB59: 0
C60: =$V$60 -> Joelle | D60: 0 | E60: 0 | F60: 0 | G60: 0 | H60: 0 | I60: 0 | J60: 0 | K60: 0 | L60: 0 | M60: 0 | N60: 0 | O60: 0 | P60: 0 | Q60: 0 | R60: 0 | S60: 0 | U60: 8 | V60: Joelle | W60: 0 | X60: 0 | Y60: 0 | Z60: 0 | AA60: 0 | AB60: 0 | AC60: 0 | AD60: 0 | AE60: 0 | AF60: 0 | AG60: 0 | AH60: 0 | AI60: 0 | AJ60: 0 | AK60: 0 | AL60: 0 | AM60: 0 | AN60: =SUM(W60:AM60) -> 0 | AQ60: =$V$79 -> - | AR60: 0 | AS60: 0 | AT60: 0 | AU60: 0 | AV60: 0 | AW60: 0 | AX60: 0 | AY60: 0 | AZ60: 0 | BA60: 0 | BB60: 0 | BC60: 0 | BD60: 0 | BE60: 0 | BF60: 0 | BG60: 0 | BH60: 0 | BK60: =$V$79 -> - | BL60: 0 | BM60: 0 | BN60: 0 | BO60: 0 | BP60: 0 | BQ60: 0 | BR60: 0 | BS60: 0 | BT60: 0 | BU60: 0 | BV60: 0 | BW60: 0 | BX60: 0 | BY60: 0 | BZ60: 0 | CA60: 0 | CB60: 0
C61: =$V$61 -> Alexia | D61: 0 | E61: 0 | F61: 0 | G61: 0 | H61: 0 | I61: 0 | J61: 0 | K61: 0 | L61: 0 | M61: 0 | N61: 0 | O61: 0 | P61: 0 | Q61: 0 | R61: 0 | S61: 0 | U61: 9 | V61: Alexia | W61: 0 | X61: 0 | Y61: 0 | Z61: 0 | AA61: 0 | AB61: 0 | AC61: 0 | AD61: 0 | AE61: 0 | AF61: 0 | AG61: 0 | AH61: 0 | AI61: 0 | AJ61: 0 | AK61: 0 | AL61: 0 | AM61: 0 | AN61: =SUM(W61:AM61) -> 0 | AQ61: =$V$80 -> - | AR61: 0 | AS61: 0 | AT61: 0 | AU61: 0 | AV61: 0 | AW61: 0 | AX61: 0 | AY61: 0 | AZ61: 0 | BA61: 0 | BB61: 0 | BC61: 0 | BD61: 0 | BE61: 0 | BF61: 0 | BG61: 0 | BH61: 0 | BK61: =$V$80 -> - | BL61: 0 | BM61: 0 | BN61: 0 | BO61: 0 | BP61: 0 | BQ61: 0 | BR61: 0 | BS61: 0 | BT61: 0 | BU61: 0 | BV61: 0 | BW61: 0 | BX61: 0 | BY61: 0 | BZ61: 0 | CA61: 0 | CB61: 0
C62: =$V$62 -> Joao | D62: 0 | E62: 0 | F62: 0 | G62: 0 | H62: 0 | I62: 0 | J62: 0 | K62: 0 | L62: 0 | M62: 0 | N62: 0 | O62: 0 | P62: 0 | Q62: 0 | R62: 0 | S62: 0 | U62: 10 | V62: Joao | W62: 0 | X62: 0 | Y62: 0 | Z62: 0 | AA62: 0 | AB62: 0 | AC62: 0 | AD62: 0 | AE62: 0 | AF62: 0 | AG62: 0 | AH62: 0 | AI62: 0 | AJ62: 0 | AK62: 0 | AL62: 0 | AM62: 0 | AN62: =SUM(W62:AM62) -> 0 | AQ62: =$V$81 -> - | AR62: 0 | AS62: 0 | AT62: 0 | AU62: 0 | AV62: 0 | AW62: 0 | AX62: 0 | AY62: 0 | AZ62: 0 | BA62: 0 | BB62: 0 | BC62: 0 | BD62: 0 | BE62: 0 | BF62: 0 | BG62: 0 | BH62: 0 | BK62: =$V$81 -> - | BL62: 0 | BM62: 0 | BN62: 0 | BO62: 0 | BP62: 0 | BQ62: 0 | BR62: 0 | BS62: 0 | BT62: 0 | BU62: 0 | BV62: 0 | BW62: 0 | BX62: 0 | BY62: 0 | BZ62: 0 | CA62: 0 | CB62: 0
C63: =$V$63 -> Maxime | D63: 0 | E63: 0 | F63: 0 | G63: 0 | H63: 0 | I63: 0 | J63: 0 | K63: 0 | L63: 0 | M63: 0 | N63: 0 | O63: 0 | P63: 0 | Q63: 0 | R63: 0 | S63: 0 | U63: 11 | V63: Maxime | W63: 0 | X63: 0 | Y63: 0 | Z63: 0 | AA63: 0 | AB63: 0 | AC63: 0 | AD63: 0 | AE63: 0 | AF63: 0 | AG63: 0 | AH63: 0 | AI63: 0 | AJ63: 0 | AK63: 0 | AL63: 0 | AM63: 0 | AN63: =SUM(W63:AM63) -> 0 | AQ63: =$V$82 -> - | AR63: 0 | AS63: 0 | AT63: 0 | AU63: 0 | AV63: 0 | AW63: 0 | AX63: 0 | AY63: 0 | AZ63: 0 | BA63: 0 | BB63: 0 | BC63: 0 | BD63: 0 | BE63: 0 | BF63: 0 | BG63: 0 | BH63: 0 | BK63: =$V$82 -> - | BL63: 0 | BM63: 0 | BN63: 0 | BO63: 0 | BP63: 0 | BQ63: 0 | BR63: 0 | BS63: 0 | BT63: 0 | BU63: 0 | BV63: 0 | BW63: 0 | BX63: 0 | BY63: 0 | BZ63: 0 | CA63: 0 | CB63: 0
C64: =$V$64 -> Alex | D64: 0 | E64: 0 | F64: 0 | G64: 0 | H64: 0 | I64: 0 | J64: 0 | K64: 0 | L64: 0 | M64: 0 | N64: 0 | O64: 0 | P64: 0 | Q64: 0 | R64: 0 | S64: 0 | U64: 12 | V64: Alex | W64: 0 | X64: 0 | Y64: 0 | Z64: 0 | AA64: 0 | AB64: 0 | AC64: 0 | AD64: 0 | AE64: 0 | AF64: 0 | AG64: 0 | AH64: 0 | AI64: 0 | AJ64: 0 | AK64: 0 | AL64: 0 | AM64: 0 | AN64: =SUM(W64:AM64) -> 0 | AQ64: =$V$83 -> - | AR64: 0 | AS64: 0 | AT64: 0 | AU64: 0 | AV64: 0 | AW64: 0 | AX64: 0 | AY64: 0 | AZ64: 0 | BA64: 0 | BB64: 0 | BC64: 0 | BD64: 0 | BE64: 0 | BF64: 0 | BG64: 0 | BH64: 0 | BK64: =$V$83 -> - | BL64: 0 | BM64: 0 | BN64: 0 | BO64: 0 | BP64: 0 | BQ64: 0 | BR64: 0 | BS64: 0 | BT64: 0 | BU64: 0 | BV64: 0 | BW64: 0 | BX64: 0 | BY64: 0 | BZ64: 0 | CA64: 0 | CB64: 0
C65: =$V$65 -> Alyssa | D65: 0 | E65: 0 | F65: 0 | G65: 0 | H65: 0 | I65: 0 | J65: 0 | K65: 0 | L65: 0 | M65: 0 | N65: 0 | O65: 0 | P65: 0 | Q65: 0 | R65: 0 | S65: 0 | U65: 13 | V65: Alyssa | W65: 0 | X65: 0 | Y65: 0 | Z65: 0 | AA65: 0 | AB65: 0 | AC65: 0 | AD65: 0 | AE65: 0 | AF65: 0 | AG65: 0 | AH65: 0 | AI65: 0 | AJ65: 0 | AK65: 0 | AL65: 0 | AM65: 0 | AN65: =SUM(W65:AM65) -> 0 | AQ65: =$V$84 -> - | AR65: 0 | AS65: 0 | AT65: 0 | AU65: 0 | AV65: 0 | AW65: 0 | AX65: 0 | AY65: 0 | AZ65: 0 | BA65: 0 | BB65: 0 | BC65: 0 | BD65: 0 | BE65: 0 | BF65: 0 | BG65: 0 | BH65: 0 | BK65: =$V$84 -> - | BL65: 0 | BM65: 0 | BN65: 0 | BO65: 0 | BP65: 0 | BQ65: 0 | BR65: 0 | BS65: 0 | BT65: 0 | BU65: 0 | BV65: 0 | BW65: 0 | BX65: 0 | BY65: 0 | BZ65: 0 | CA65: 0 | CB65: 0
C66: =$V$66 -> Amanda | D66: 0 | E66: 0 | F66: 0 | G66: 0 | H66: 0 | I66: 0 | J66: 0 | K66: 0 | L66: 0 | M66: 0 | N66: 0 | O66: 0 | P66: 0 | Q66: 0 | R66: 0 | S66: 0 | U66: 14 | V66: Amanda | W66: 0 | X66: 0 | Y66: 0 | Z66: 0 | AA66: 0 | AB66: 0 | AC66: 0 | AD66: 0 | AE66: 0 | AF66: 0 | AG66: 0 | AH66: 0 | AI66: 0 | AJ66: 0 | AK66: 0 | AL66: 0 | AM66: 0 | AN66: =SUM(W66:AM66) -> 0 | AQ66: =$V$85 -> - | AR66: 0 | AS66: 0 | AT66: 0 | AU66: 0 | AV66: 0 | AW66: 0 | AX66: 0 | AY66: 0 | AZ66: 0 | BA66: 0 | BB66: 0 | BC66: 0 | BD66: 0 | BE66: 0 | BF66: 0 | BG66: 0 | BH66: 0 | BK66: =$V$85 -> - | BL66: 0 | BM66: 0 | BN66: 0 | BO66: 0 | BP66: 0 | BQ66: 0 | BR66: 0 | BS66: 0 | BT66: 0 | BU66: 0 | BV66: 0 | BW66: 0 | BX66: 0 | BY66: 0 | BZ66: 0 | CA66: 0 | CB66: 0
C67: =$V$67 -> Antoine | D67: 0 | E67: 0 | F67: 0 | G67: 0 | H67: 0 | I67: 0 | J67: 0 | K67: 0 | L67: 0 | M67: 0 | N67: 0 | O67: 0 | P67: 0 | Q67: 0 | R67: 0 | S67: 0 | U67: 15 | V67: Antoine | W67: 0 | X67: 0 | Y67: 0 | Z67: 0 | AA67: 0 | AB67: 0 | AC67: 0 | AD67: 0 | AE67: 0 | AF67: 0 | AG67: 0 | AH67: 0 | AI67: 0 | AJ67: 0 | AK67: 0 | AL67: 0 | AM67: 0 | AN67: =SUM(W67:AM67) -> 0 | AQ67: =$V$86 -> - | AR67: 0 | AS67: 0 | AT67: 0 | AU67: 0 | AV67: 0 | AW67: 0 | AX67: 0 | AY67: 0 | AZ67: 0 | BA67: 0 | BB67: 0 | BC67: 0 | BD67: 0 | BE67: 0 | BF67: 0 | BG67: 0 | BH67: 0 | BK67: =$V$86 -> - | BL67: 0 | BM67: 0 | BN67: 0 | BO67: 0 | BP67: 0 | BQ67: 0 | BR67: 0 | BS67: 0 | BT67: 0 | BU67: 0 | BV67: 0 | BW67: 0 | BX67: 0 | BY67: 0 | BZ67: 0 | CA67: 0 | CB67: 0
C68: =$V$68 -> Beatriz | D68: 0 | E68: 0 | F68: 0 | G68: 0 | H68: 0 | I68: 0 | J68: 0 | K68: 0 | L68: 0 | M68: 0 | N68: 0 | O68: 0 | P68: 0 | Q68: 0 | R68: 0 | S68: 0 | U68: 16 | V68: Beatriz | W68: 0 | X68: 0 | Y68: 0 | Z68: 0 | AA68: 0 | AB68: 0 | AC68: 0 | AD68: 0 | AE68: 0 | AF68: 0 | AG68: 0 | AH68: 0 | AI68: 0 | AJ68: 0 | AK68: 0 | AL68: 0 | AM68: 0 | AN68: =SUM(W68:AM68) -> 0 | AQ68: =$V$87 -> - | AR68: 0 | AS68: 0 | AT68: 0 | AU68: 0 | AV68: 0 | AW68: 0 | AX68: 0 | AY68: 0 | AZ68: 0 | BA68: 0 | BB68: 0 | BC68: 0 | BD68: 0 | BE68: 0 | BF68: 0 | BG68: 0 | BH68: 0 | BK68: =$V$87 -> - | BL68: 0 | BM68: 0 | BN68: 0 | BO68: 0 | BP68: 0 | BQ68: 0 | BR68: 0 | BS68: 0 | BT68: 0 | BU68: 0 | BV68: 0 | BW68: 0 | BX68: 0 | BY68: 0 | BZ68: 0 | CA68: 0 | CB68: 0
C69: =$V$69 -> Charelle | D69: 0 | E69: 0 | F69: 0 | G69: 0 | H69: 0 | I69: 0 | J69: 0 | K69: 0 | L69: 0 | M69: 0 | N69: 0 | O69: 0 | P69: 0 | Q69: 0 | R69: 0 | S69: 0 | U69: 17 | V69: Charelle | W69: 0 | X69: 0 | Y69: 0 | Z69: 0 | AA69: 0 | AB69: 0 | AC69: 0 | AD69: 0 | AE69: 0 | AF69: 0 | AG69: 0 | AH69: 0 | AI69: 0 | AJ69: 0 | AK69: 0 | AL69: 0 | AM69: 0 | AN69: =SUM(W69:AM69) -> 0 | AQ69: =$V$88 -> - | AR69: 0 | AS69: 0 | AT69: 0 | AU69: 0 | AV69: 0 | AW69: 0 | AX69: 0 | AY69: 0 | AZ69: 0 | BA69: 0 | BB69: 0 | BC69: 0 | BD69: 0 | BE69: 0 | BF69: 0 | BG69: 0 | BH69: 0 | BK69: =$V$88 -> - | BL69: 0 | BM69: 0 | BN69: 0 | BO69: 0 | BP69: 0 | BQ69: 0 | BR69: 0 | BS69: 0 | BT69: 0 | BU69: 0 | BV69: 0 | BW69: 0 | BX69: 0 | BY69: 0 | BZ69: 0 | CA69: 0 | CB69: 0
C70: =$V$70 -> Dimitri | D70: 0 | E70: 0 | F70: 0 | G70: 0 | H70: 0 | I70: 0 | J70: 0 | K70: 0 | L70: 0 | M70: 0 | N70: 0 | O70: 0 | P70: 0 | Q70: 0 | R70: 0 | S70: 0 | U70: 18 | V70: Dimitri | W70: 0 | X70: 0 | Y70: 0 | Z70: 0 | AA70: 0 | AB70: 0 | AC70: 0 | AD70: 0 | AE70: 0 | AF70: 0 | AG70: 0 | AH70: 0 | AI70: 0 | AJ70: 0 | AK70: 0 | AL70: 0 | AM70: 0 | AN70: =SUM(W70:AM70) -> 0 | AQ70: =$V$89 -> - | AR70: 0 | AS70: 0 | AT70: 0 | AU70: 0 | AV70: 0 | AW70: 0 | AX70: 0 | AY70: 0 | AZ70: 0 | BA70: 0 | BB70: 0 | BC70: 0 | BD70: 0 | BE70: 0 | BF70: 0 | BG70: 0 | BH70: 0 | BK70: =$V$89 -> - | BL70: 0 | BM70: 0 | BN70: 0 | BO70: 0 | BP70: 0 | BQ70: 0 | BR70: 0 | BS70: 0 | BT70: 0 | BU70: 0 | BV70: 0 | BW70: 0 | BX70: 0 | BY70: 0 | BZ70: 0 | CA70: 0 | CB70: 0
C71: =$V$71 -> Marina | D71: 0 | E71: 0 | F71: 0 | G71: 0 | H71: 0 | I71: 0 | J71: 0 | K71: 0 | L71: 0 | M71: 0 | N71: 0 | O71: 0 | P71: 0 | Q71: 0 | R71: 0 | S71: 0 | U71: 19 | V71: Marina | W71: 0 | X71: 0 | Y71: 0 | Z71: 0 | AA71: 0 | AB71: 0 | AC71: 0 | AD71: 0 | AE71: 0 | AF71: 0 | AG71: 0 | AH71: 0 | AI71: 0 | AJ71: 0 | AK71: 0 | AL71: 0 | AM71: 0 | AN71: =SUM(W71:AM71) -> 0 | AQ71: =$V$90 -> - | AR71: 0 | AS71: 0 | AT71: 0 | AU71: 0 | AV71: 0 | AW71: 0 | AX71: 0 | AY71: 0 | AZ71: 0 | BA71: 0 | BB71: 0 | BC71: 0 | BD71: 0 | BE71: 0 | BF71: 0 | BG71: 0 | BH71: 0 | BK71: =$V$90 -> - | BL71: 0 | BM71: 0 | BN71: 0 | BO71: 0 | BP71: 0 | BQ71: 0 | BR71: 0 | BS71: 0 | BT71: 0 | BU71: 0 | BV71: 0 | BW71: 0 | BX71: 0 | BY71: 0 | BZ71: 0 | CA71: 0 | CB71: 0
...

Sheet STAFF PLANNING FINAL
C2: 16h | D2: 17h | E2: 18h | F2: 19h | G2: 20h | H2: 21h | I2: 22h | J2: 23h | K2: 00h | L2: 01h | M2: 02h | N2: 03h | O2: 04h | P2: 05h | Q2: 06h | R2: 07h | S2: 08h
A3: 1 | B3: Jennifer | C3: {=IF(PER!W53=0,"",IF((PER!AR34+PER!AR74+PER!AR114+PER!AR154+PER!AR194+PER!AR234+PER!AR274+PER!AR314+PER!AR354+PER!AR394+PER!AR434+PER!AR474+PER!AR514+PER!AR554+PER!AR594)=0,"",_xlfn.IFS(PER!AR34=1,PER!$V$34,PER!AR74=1,PER!$V$35,PER!AR114=1,PER!$V$36,PER!AR154=1,PER!$V$37,PER!AR194=1,PER!$V$38,PER!AR234=1,PER!$V$39,PER!AR274=1,PER!$V$40,PER!AR314=1,PER!$V$41,PER!AR354=1,PER!$V$42,PER!AR394=1,PER!$V$43,PER!AR434=1,PER!$V$44,PER!AR474=1,PER!$V$45,PER!AR514=1,PER!$V$46,PER!AR554=1,PER!$V$47,PER!AR594=1,PER!$V$48)))} -> Entry | D3: {=IF(PER!X53=0,"",IF((PER!AS34+PER!AS74+PER!AS114+PER!AS154+PER!AS194+PER!AS234+PER!AS274+PER!AS314+PER!AS354+PER!AS394+PER!AS434+PER!AS474+PER!AS514+PER!AS554+PER!AS594)=0,"",_xlfn.IFS(PER!AS34=1,PER!$V$34,PER!AS74=1,PER!$V$35,PER!AS114=1,PER!$V$36,PER!AS154=1,PER!$V$37,PER!AS194=1,PER!$V$38,PER!AS234=1,PER!$V$39,PER!AS274=1,PER!$V$40,PER!AS314=1,PER!$V$41,PER!AS354=1,PER!$V$42,PER!AS394=1,PER!$V$43,PER!AS434=1,PER!$V$44,PER!AS474=1,PER!$V$45,PER!AS514=1,PER!$V$46,PER!AS554=1,PER!$V$47,PER!AS594=1,PER!$V$48)))} -> Set up | E3: {=IF(PER!Y53=0,"",IF((PER!AT34+PER!AT74+PER!AT114+PER!AT154+PER!AT194+PER!AT234+PER!AT274+PER!AT314+PER!AT354+PER!AT394+PER!AT434+PER!AT474+PER!AT514+PER!AT554+PER!AT594)=0,"",_xlfn.IFS(PER!AT34=1,PER!$V$34,PER!AT74=1,PER!$V$35,PER!AT114=1,PER!$V$36,PER!AT154=1,PER!$V$37,PER!AT194=1,PER!$V$38,PER!AT234=1,PER!$V$39,PER!AT274=1,PER!$V$40,PER!AT314=1,PER!$V$41,PER!AT354=1,PER!$V$42,PER!AT394=1,PER!$V$43,PER!AT434=1,PER!$V$44,PER!AT474=1,PER!$V$45,PER!AT514=1,PER!$V$46,PER!AT554=1,PER!$V$47,PER!AT594=1,PER!$V$48)))} -> Bar | F3: {=IF(PER!Z53=0,"",IF((PER!AU34+PER!AU74+PER!AU114+PER!AU154+PER!AU194+PER!AU234+PER!AU274+PER!AU314+PER!AU354+PER!AU394+PER!AU434+PER!AU474+PER!AU514+PER!AU554+PER!AU594)=0,"",_xlfn.IFS(PER!AU34=1,PER!$V$34,PER!AU74=1,PER!$V$35,PER!AU114=1,PER!$V$36,PER!AU154=1,PER!$V$37,PER!AU194=1,PER!$V$38,PER!AU234=1,PER!$V$39,PER!AU274=1,PER!$V$40,PER!AU314=1,PER!$V$41,PER!AU354=1,PER!$V$42,PER!AU394=1,PER!$V$43,PER!AU434=1,PER!$V$44,PER!AU474=1,PER!$V$45,PER!AU514=1,PER!$V$46,PER!AU554=1,PER!$V$47,PER!AU594=1,PER!$V$48)))} -> Entry | G3: {=IF(PER!AA53=0,"",IF((PER!AV34+PER!AV74+PER!AV114+PER!AV154+PER!AV194+PER!AV234+PER!AV274+PER!AV314+PER!AV354+PER!AV394+PER!AV434+PER!AV474+PER!AV514+PER!AV554+PER!AV594)=0,"",_xlfn.IFS(PER!AV34=1,PER!$V$34,PER!AV74=1,PER!$V$35,PER!AV114=1,PER!$V$36,PER!AV154=1,PER!$V$37,PER!AV194=1,PER!$V$38,PER!AV234=1,PER!$V$39,PER!AV274=1,PER!$V$40,PER!AV314=1,PER!$V$41,PER!AV354=1,PER!$V$42,PER!AV394=1,PER!$V$43,PER!AV434=1,PER!$V$44,PER!AV474=1,PER!$V$45,PER!AV514=1,PER!$V$46,PER!AV554=1,PER!$V$47,PER!AV594=1,PER!$V$48)))} -> Set up | H3: {=IF(PER!AB53=0,"",IF((PER!AW34+PER!AW74+PER!AW114+PER!AW154+PER!AW194+PER!AW234+PER!AW274+PER!AW314+PER!AW354+PER!AW394+PER!AW434+PER!AW474+PER!AW514+PER!AW554+PER!AW594)=0,"",_xlfn.IFS(PER!AW34=1,PER!$V$34,PER!AW74=1,PER!$V$35,PER!AW114=1,PER!$V$36,PER!AW154=1,PER!$V$37,PER!AW194=1,PER!$V$38,PER!AW234=1,PER!$V$39,PER!AW274=1,PER!$V$40,PER!AW314=1,PER!$V$41,PER!AW354=1,PER!$V$42,PER!AW394=1,PER!$V$43,PER!AW434=1,PER!$V$44,PER!AW474=1,PER!$V$45,PER!AW514=1,PER!$V$46,PER!AW554=1,PER!$V$47,PER!AW594=1,PER!$V$48)))} -> Rez | I3: {=IF(PER!AC53=0,"",IF((PER!AX34+PER!AX74+PER!AX114+PER!AX154+PER!AX194+PER!AX234+PER!AX274+PER!AX314+PER!AX354+PER!AX394+PER!AX434+PER!AX474+PER!AX514+PER!AX554+PER!AX594)=0,"",_xlfn.IFS(PER!AX34=1,PER!$V$34,PER!AX74=1,PER!$V$35,PER!AX114=1,PER!$V$36,PER!AX154=1,PER!$V$37,PER!AX194=1,PER!$V$38,PER!AX234=1,PER!$V$39,PER!AX274=1,PER!$V$40,PER!AX314=1,PER!$V$41,PER!AX354=1,PER!$V$42,PER!AX394=1,PER!$V$43,PER!AX434=1,PER!$V$44,PER!AX474=1,PER!$V$45,PER!AX514=1,PER!$V$46,PER!AX554=1,PER!$V$47,PER!AX594=1,PER!$V$48)))} -> Set up | J3: {=IF(PER!AD53=0,"",IF((PER!AY34+PER!AY74+PER!AY114+PER!AY154+PER!AY194+PER!AY234+PER!AY274+PER!AY314+PER!AY354+PER!AY394+PER!AY434+PER!AY474+PER!AY514+PER!AY554+PER!AY594)=0,"",_xlfn.IFS(PER!AY34=1,PER!$V$34,PER!AY74=1,PER!$V$35,PER!AY114=1,PER!$V$36,PER!AY154=1,PER!$V$37,PER!AY194=1,PER!$V$38,PER!AY234=1,PER!$V$39,PER!AY274=1,PER!$V$40,PER!AY314=1,PER!$V$41,PER!AY354=1,PER!$V$42,PER!AY394=1,PER!$V$43,PER!AY434=1,PER!$V$44,PER!AY474=1,PER!$V$45,PER!AY514=1,PER!$V$46,PER!AY554=1,PER!$V$47,PER!AY594=1,PER!$V$48)))} -> Rez | ... S3: {=IF(PER!AM53=0,"",IF((PER!BH34+PER!BH74+PER!BH114+PER!BH154+PER!BH194+PER!BH234+PER!BH274+PER!BH314+PER!BH354+PER!BH394+PER!BH434+PER!BH474+PER!BH514+PER!BH554+PER!BH594)=0,"",_xlfn.IFS(PER!BH34=1,PER!$V$34,PER!BH74=1,PER!$V$35,PER!BH114=1,PER!$V$36,PER!BH154=1,PER!$V$37,PER!BH194=1,PER!$V$38,PER!BH234=1,PER!$V$39,PER!BH274=1,PER!$V$40,PER!BH314=1,PER!$V$41,PER!BH354=1,PER!$V$42,PER!BH394=1,PER!$V$43,PER!BH434=1,PER!$V$44,PER!BH474=1,PER!$V$45,PER!BH514=1,PER!$V$46,PER!BH554=1,PER!$V$47,PER!BH594=1,PER!$V$48)))}
A4: 2 | B4: Galileo | C4: {=IF(PER!W54=0,"",IF((PER!AR35+PER!AR75+PER!AR115+PER!AR155+PER!AR195+PER!AR235+PER!AR275+PER!AR315+PER!AR355+PER!AR395+PER!AR435+PER!AR475+PER!AR515+PER!AR555+PER!AR595)=0,"",_xlfn.IFS(PER!AR35=1,PER!$V$34,PER!AR75=1,PER!$V$35,PER!AR115=1,PER!$V$36,PER!AR155=1,PER!$V$37,PER!AR195=1,PER!$V$38,PER!AR235=1,PER!$V$39,PER!AR275=1,PER!$V$40,PER!AR315=1,PER!$V$41,PER!AR355=1,PER!$V$42,PER!AR395=1,PER!$V$43,PER!AR435=1,PER!$V$44,PER!AR475=1,PER!$V$45,PER!AR515=1,PER!$V$46,PER!AR555=1,PER!$V$47,PER!AR595=1,PER!$V$48)))} -> C-mix | D4: {=IF(PER!X54=0,"",IF((PER!AS35+PER!AS75+PER!AS115+PER!AS155+PER!AS195+PER!AS235+PER!AS275+PER!AS315+PER!AS355+PER!AS395+PER!AS435+PER!AS475+PER!AS515+PER!AS555+PER!AS595)=0,"",_xlfn.IFS(PER!AS35=1,PER!$V$34,PER!AS75=1,PER!$V$35,PER!AS115=1,PER!$V$36,PER!AS155=1,PER!$V$37,PER!AS195=1,PER!$V$38,PER!AS235=1,PER!$V$39,PER!AS275=1,PER!$V$40,PER!AS315=1,PER!$V$41,PER!AS355=1,PER!$V$42,PER!AS395=1,PER!$V$43,PER!AS435=1,PER!$V$44,PER!AS475=1,PER!$V$45,PER!AS515=1,PER!$V$46,PER!AS555=1,PER!$V$47,PER!AS595=1,PER!$V$48)))} -> Entry | E4: {=IF(PER!Y54=0,"",IF((PER!AT35+PER!AT75+PER!AT115+PER!AT155+PER!AT195+PER!AT235+PER!AT275+PER!AT315+PER!AT355+PER!AT395+PER!AT435+PER!AT475+PER!AT515+PER!AT555+PER!AT595)=0,"",_xlfn.IFS(PER!AT35=1,PER!$V$34,PER!AT75=1,PER!$V$35,PER!AT115=1,PER!$V$36,PER!AT155=1,PER!$V$37,PER!AT195=1,PER!$V$38,PER!AT235=1,PER!$V$39,PER!AT275=1,PER!$V$40,PER!AT315=1,PER!$V$41,PER!AT355=1,PER!$V$42,PER!AT395=1,PER!$V$43,PER!AT435=1,PER!$V$44,PER!AT475=1,PER!$V$45,PER!AT515=1,PER!$V$46,PER!AT555=1,PER!$V$47,PER!AT595=1,PER!$V$48)))} -> C-mix | F4: {=IF(PER!Z54=0,"",IF((PER!AU35+PER!AU75+PER!AU115+PER!AU155+PER!AU195+PER!AU235+PER!AU275+PER!AU315+PER!AU355+PER!AU395+PER!AU435+PER!AU475+PER!AU515+PER!AU555+PER!AU595)=0,"",_xlfn.IFS(PER!AU35=1,PER!$V$34,PER!AU75=1,PER!$V$35,PER!AU115=1,PER!$V$36,PER!AU155=1,PER!$V$37,PER!AU195=1,PER!$V$38,PER!AU235=1,PER!$V$39,PER!AU275=1,PER!$V$40,PER!AU315=1,PER!$V$41,PER!AU355=1,PER!$V$42,PER!AU395=1,PER!$V$43,PER!AU435=1,PER!$V$44,PER!AU475=1,PER!$V$45,PER!AU515=1,PER!$V$46,PER!AU555=1,PER!$V$47,PER!AU595=1,PER!$V$48)))} -> Bar | G4: {=IF(PER!AA54=0,"",IF((PER!AV35+PER!AV75+PER!AV115+PER!AV155+PER!AV195+PER!AV235+PER!AV275+PER!AV315+PER!AV355+PER!AV395+PER!AV435+PER!AV475+PER!AV515+PER!AV555+PER!AV595)=0,"",_xlfn.IFS(PER!AV35=1,PER!$V$34,PER!AV75=1,PER!$V$35,PER!AV115=1,PER!$V$36,PER!AV155=1,PER!$V$37,PER!AV195=1,PER!$V$38,PER!AV235=1,PER!$V$39,PER!AV275=1,PER!$V$40,PER!AV315=1,PER!$V$41,PER!AV355=1,PER!$V$42,PER!AV395=1,PER!$V$43,PER!AV435=1,PER!$V$44,PER!AV475=1,PER!$V$45,PER!AV515=1,PER!$V$46,PER!AV555=1,PER!$V$47,PER!AV595=1,PER!$V$48)))} -> Level | H4: {=IF(PER!AB54=0,"",IF((PER!AW35+PER!AW75+PER!AW115+PER!AW155+PER!AW195+PER!AW235+PER!AW275+PER!AW315+PER!AW355+PER!AW395+PER!AW435+PER!AW475+PER!AW515+PER!AW555+PER!AW595)=0,"",_xlfn.IFS(PER!AW35=1,PER!$V$34,PER!AW75=1,PER!$V$35,PER!AW115=1,PER!$V$36,PER!AW155=1,PER!$V$37,PER!AW195=1,PER!$V$38,PER!AW235=1,PER!$V$39,PER!AW275=1,PER!$V$40,PER!AW315=1,PER!$V$41,PER!AW355=1,PER!$V$42,PER!AW395=1,PER!$V$43,PER!AW435=1,PER!$V$44,PER!AW475=1,PER!$V$45,PER!AW515=1,PER!$V$46,PER!AW555=1,PER!$V$47,PER!AW595=1,PER!$V$48)))} -> Bar | I4: {=IF(PER!AC54=0,"",IF((PER!AX35+PER!AX75+PER!AX115+PER!AX155+PER!AX195+PER!AX235+PER!AX275+PER!AX315+PER!AX355+PER!AX395+PER!AX435+PER!AX475+PER!AX515+PER!AX555+PER!AX595)=0,"",_xlfn.IFS(PER!AX35=1,PER!$V$34,PER!AX75=1,PER!$V$35,PER!AX115=1,PER!$V$36,PER!AX155=1,PER!$V$37,PER!AX195=1,PER!$V$38,PER!AX235=1,PER!$V$39,PER!AX275=1,PER!$V$40,PER!AX315=1,PER!$V$41,PER!AX355=1,PER!$V$42,PER!AX395=1,PER!$V$43,PER!AX435=1,PER!$V$44,PER!AX475=1,PER!$V$45,PER!AX515=1,PER!$V$46,PER!AX555=1,PER!$V$47,PER!AX595=1,PER!$V$48)))} -> Rez | J4: {=IF(PER!AD54=0,"",IF((PER!AY35+PER!AY75+PER!AY115+PER!AY155+PER!AY195+PER!AY235+PER!AY275+PER!AY315+PER!AY355+PER!AY395+PER!AY435+PER!AY475+PER!AY515+PER!AY555+PER!AY595)=0,"",_xlfn.IFS(PER!AY35=1,PER!$V$34,PER!AY75=1,PER!$V$35,PER!AY115=1,PER!$V$36,PER!AY155=1,PER!$V$37,PER!AY195=1,PER!$V$38,PER!AY235=1,PER!$V$39,PER!AY275=1,PER!$V$40,PER!AY315=1,PER!$V$41,PER!AY355=1,PER!$V$42,PER!AY395=1,PER!$V$43,PER!AY435=1,PER!$V$44,PER!AY475=1,PER!$V$45,PER!AY515=1,PER!$V$46,PER!AY555=1,PER!$V$47,PER!AY595=1,PER!$V$48)))} -> C-mix | ... S4: {=IF(PER!AM54=0,"",IF((PER!BH35+PER!BH75+PER!BH115+PER!BH155+PER!BH195+PER!BH235+PER!BH275+PER!BH315+PER!BH355+PER!BH395+PER!BH435+PER!BH475+PER!BH515+PER!BH555+PER!BH595)=0,"",_xlfn.IFS(PER!BH35=1,PER!$V$34,PER!BH75=1,PER!$V$35,PER!BH115=1,PER!$V$36,PER!BH155=1,PER!$V$37,PER!BH195=1,PER!$V$38,PER!BH235=1,PER!$V$39,PER!BH275=1,PER!$V$40,PER!BH315=1,PER!$V$41,PER!BH355=1,PER!$V$42,PER!BH395=1,PER!$V$43,PER!BH435=1,PER!$V$44,PER!BH475=1,PER!$V$45,PER!BH515=1,PER!$V$46,PER!BH555=1,PER!$V$47,PER!BH595=1,PER!$V$48)))}
A5: 3 | B5: Óscar | C5: {=IF(PER!W55=0,"",IF((PER!AR36+PER!AR76+PER!AR116+PER!AR156+PER!AR196+PER!AR236+PER!AR276+PER!AR316+PER!AR356+PER!AR396+PER!AR436+PER!AR476+PER!AR516+PER!AR556+PER!AR596)=0,"",_xlfn.IFS(PER!AR36=1,PER!$V$34,PER!AR76=1,PER!$V$35,PER!AR116=1,PER!$V$36,PER!AR156=1,PER!$V$37,PER!AR196=1,PER!$V$38,PER!AR236=1,PER!$V$39,PER!AR276=1,PER!$V$40,PER!AR316=1,PER!$V$41,PER!AR356=1,PER!$V$42,PER!AR396=1,PER!$V$43,PER!AR436=1,PER!$V$44,PER!AR476=1,PER!$V$45,PER!AR516=1,PER!$V$46,PER!AR556=1,PER!$V$47,PER!AR596=1,PER!$V$48)))} -> Çapèse | D5: {=IF(PER!X55=0,"",IF((PER!AS36+PER!AS76+PER!AS116+PER!AS156+PER!AS196+PER!AS236+PER!AS276+PER!AS316+PER!AS356+PER!AS396+PER!AS436+PER!AS476+PER!AS516+PER!AS556+PER!AS596)=0,"",_xlfn.IFS(PER!AS36=1,PER!$V$34,PER!AS76=1,PER!$V$35,PER!AS116=1,PER!$V$36,PER!AS156=1,PER!$V$37,PER!AS196=1,PER!$V$38,PER!AS236=1,PER!$V$39,PER!AS276=1,PER!$V$40,PER!AS316=1,PER!$V$41,PER!AS356=1,PER!$V$42,PER!AS396=1,PER!$V$43,PER!AS436=1,PER!$V$44,PER!AS476=1,PER!$V$45,PER!AS516=1,PER!$V$46,PER!AS556=1,PER!$V$47,PER!AS596=1,PER!$V$48)))} -> Rez | E5: {=IF(PER!Y55=0,"",IF((PER!AT36+PER!AT76+PER!AT116+PER!AT156+PER!AT196+PER!AT236+PER!AT276+PER!AT316+PER!AT356+PER!AT396+PER!AT436+PER!AT476+PER!AT516+PER!AT556+PER!AT596)=0,"",_xlfn.IFS(PER!AT36=1,PER!$V$34,PER!AT76=1,PER!$V$35,PER!AT116=1,PER!$V$36,PER!AT156=1,PER!$V$37,PER!AT196=1,PER!$V$38,PER!AT236=1,PER!$V$39,PER!AT276=1,PER!$V$40,PER!AT316=1,PER!$V$41,PER!AT356=1,PER!$V$42,PER!AT396=1,PER!$V$43,PER!AT436=1,PER!$V$44,PER!AT476=1,PER!$V$45,PER!AT516=1,PER!$V$46,PER!AT556=1,PER!$V$47,PER!AT596=1,PER!$V$48)))} -> Entry | F5: {=IF(PER!Z55=0,"",IF((PER!AU36+PER!AU76+PER!AU116+PER!AU156+PER!AU196+PER!AU236+PER!AU276+PER!AU316+PER!AU356+PER!AU396+PER!AU436+PER!AU476+PER!AU516+PER!AU556+PER!AU596)=0,"",_xlfn.IFS(PER!AU36=1,PER!$V$34,PER!AU76=1,PER!$V$35,PER!AU116=1,PER!$V$36,PER!AU156=1,PER!$V$37,PER!AU196=1,PER!$V$38,PER!AU236=1,PER!$V$39,PER!AU276=1,PER!$V$40,PER!AU316=1,PER!$V$41,PER!AU356=1,PER!$V$42,PER!AU396=1,PER!$V$43,PER!AU436=1,PER!$V$44,PER!AU476=1,PER!$V$45,PER!AU516=1,PER!$V$46,PER!AU556=1,PER!$V$47,PER!AU596=1,PER!$V$48)))} -> Rez | G5: {=IF(PER!AA55=0,"",IF((PER!AV36+PER!AV76+PER!AV116+PER!AV156+PER!AV196+PER!AV236+PER!AV276+PER!AV316+PER!AV356+PER!AV396+PER!AV436+PER!AV476+PER!AV516+PER!AV556+PER!AV596)=0,"",_xlfn.IFS(PER!AV36=1,PER!$V$34,PER!AV76=1,PER!$V$35,PER!AV116=1,PER!$V$36,PER!AV156=1,PER!$V$37,PER!AV196=1,PER!$V$38,PER!AV236=1,PER!$V$39,PER!AV276=1,PER!$V$40,PER!AV316=1,PER!$V$41,PER!AV356=1,PER!$V$42,PER!AV396=1,PER!$V$43,PER!AV436=1,PER!$V$44,PER!AV476=1,PER!$V$45,PER!AV516=1,PER!$V$46,PER!AV556=1,PER!$V$47,PER!AV596=1,PER!$V$48)))} -> C-mix | H5: {=IF(PER!AB55=0,"",IF((PER!AW36+PER!AW76+PER!AW116+PER!AW156+PER!AW196+PER!AW236+PER!AW276+PER!AW316+PER!AW356+PER!AW396+PER!AW436+PER!AW476+PER!AW516+PER!AW556+PER!AW596)=0,"",_xlfn.IFS(PER!AW36=1,PER!$V$34,PER!AW76=1,PER!$V$35,PER!AW116=1,PER!$V$36,PER!AW156=1,PER!$V$37,PER!AW196=1,PER!$V$38,PER!AW236=1,PER!$V$39,PER!AW276=1,PER!$V$40,PER!AW316=1,PER!$V$41,PER!AW356=1,PER!$V$42,PER!AW396=1,PER!$V$43,PER!AW436=1,PER!$V$44,PER!AW476=1,PER!$V$45,PER!AW516=1,PER!$V$46,PER!AW556=1,PER!$V$47,PER!AW596=1,PER!$V$48)))} -> Level | I5: {=IF(PER!AC55=0,"",IF((PER!AX36+PER!AX76+PER!AX116+PER!AX156+PER!AX196+PER!AX236+PER!AX276+PER!AX316+PER!AX356+PER!AX396+PER!AX436+PER!AX476+PER!AX516+PER!AX556+PER!AX596)=0,"",_xlfn.IFS(PER!AX36=1,PER!$V$34,PER!AX76=1,PER!$V$35,PER!AX116=1,PER!$V$36,PER!AX156=1,PER!$V$37,PER!AX196=1,PER!$V$38,PER!AX236=1,PER!$V$39,PER!AX276=1,PER!$V$40,PER!AX316=1,PER!$V$41,PER!AX356=1,PER!$V$42,PER!AX396=1,PER!$V$43,PER!AX436=1,PER!$V$44,PER!AX476=1,PER!$V$45,PER!AX516=1,PER!$V$46,PER!AX556=1,PER!$V$47,PER!AX596=1,PER!$V$48)))} -> C-mix | J5: {=IF(PER!AD55=0,"",IF((PER!AY36+PER!AY76+PER!AY116+PER!AY156+PER!AY196+PER!AY236+PER!AY276+PER!AY316+PER!AY356+PER!AY396+PER!AY436+PER!AY476+PER!AY516+PER!AY556+PER!AY596)=0,"",_xlfn.IFS(PER!AY36=1,PER!$V$34,PER!AY76=1,PER!$V$35,PER!AY116=1,PER!$V$36,PER!AY156=1,PER!$V$37,PER!AY196=1,PER!$V$38,PER!AY236=1,PER!$V$39,PER!AY276=1,PER!$V$40,PER!AY316=1,PER!$V$41,PER!AY356=1,PER!$V$42,PER!AY396=1,PER!$V$43,PER!AY436=1,PER!$V$44,PER!AY476=1,PER!$V$45,PER!AY516=1,PER!$V$46,PER!AY556=1,PER!$V$47,PER!AY596=1,PER!$V$48)))} -> Bar | ... S5: {=IF(PER!AM55=0,"",IF((PER!BH36+PER!BH76+PER!BH116+PER!BH156+PER!BH196+PER!BH236+PER!BH276+PER!BH316+PER!BH356+PER!BH396+PER!BH436+PER!BH476+PER!BH516+PER!BH556+PER!BH596)=0,"",_xlfn.IFS(PER!BH36=1,PER!$V$34,PER!BH76=1,PER!$V$35,PER!BH116=1,PER!$V$36,PER!BH156=1,PER!$V$37,PER!BH196=1,PER!$V$38,PER!BH236=1,PER!$V$39,PER!BH276=1,PER!$V$40,PER!BH316=1,PER!$V$41,PER!BH356=1,PER!$V$42,PER!BH396=1,PER!$V$43,PER!BH436=1,PER!$V$44,PER!BH476=1,PER!$V$45,PER!BH516=1,PER!$V$46,PER!BH556=1,PER!$V$47,PER!BH596=1,PER!$V$48)))}
A6: 4 | B6: Sebastián | C6: {=IF(PER!W56=0,"",IF((PER!AR37+PER!AR77+PER!AR117+PER!AR157+PER!AR197+PER!AR237+PER!AR277+PER!AR317+PER!AR357+PER!AR397+PER!AR437+PER!AR477+PER!AR517+PER!AR557+PER!AR597)=0,"",_xlfn.IFS(PER!AR37=1,PER!$V$34,PER!AR77=1,PER!$V$35,PER!AR117=1,PER!$V$36,PER!AR157=1,PER!$V$37,PER!AR197=1,PER!$V$38,PER!AR237=1,PER!$V$39,PER!AR277=1,PER!$V$40,PER!AR317=1,PER!$V$41,PER!AR357=1,PER!$V$42,PER!AR397=1,PER!$V$43,PER!AR437=1,PER!$V$44,PER!AR477=1,PER!$V$45,PER!AR517=1,PER!$V$46,PER!AR557=1,PER!$V$47,PER!AR597=1,PER!$V$48)))} -> Rez | D6: {=IF(PER!X56=0,"",IF((PER!AS37+PER!AS77+PER!AS117+PER!AS157+PER!AS197+PER!AS237+PER!AS277+PER!AS317+PER!AS357+PER!AS397+PER!AS437+PER!AS477+PER!AS517+PER!AS557+PER!AS597)=0,"",_xlfn.IFS(PER!AS37=1,PER!$V$34,PER!AS77=1,PER!$V$35,PER!AS117=1,PER!$V$36,PER!AS157=1,PER!$V$37,PER!AS197=1,PER!$V$38,PER!AS237=1,PER!$V$39,PER!AS277=1,PER!$V$40,PER!AS317=1,PER!$V$41,PER!AS357=1,PER!$V$42,PER!AS397=1,PER!$V$43,PER!AS437=1,PER!$V$44,PER!AS477=1,PER!$V$45,PER!AS517=1,PER!$V$46,PER!AS557=1,PER!$V$47,PER!AS597=1,PER!$V$48)))} -> Bar | E6: {=IF(PER!Y56=0,"",IF((PER!AT37+PER!AT77+PER!AT117+PER!AT157+PER!AT197+PER!AT237+PER!AT277+PER!AT317+PER!AT357+PER!AT397+PER!AT437+PER!AT477+PER!AT517+PER!AT557+PER!AT597)=0,"",_xlfn.IFS(PER!AT37=1,PER!$V$34,PER!AT77=1,PER!$V$35,PER!AT117=1,PER!$V$36,PER!AT157=1,PER!$V$37,PER!AT197=1,PER!$V$38,PER!AT237=1,PER!$V$39,PER!AT277=1,PER!$V$40,PER!AT317=1,PER!$V$41,PER!AT357=1,PER!$V$42,PER!AT397=1,PER!$V$43,PER!AT437=1,PER!$V$44,PER!AT477=1,PER!$V$45,PER!AT517=1,PER!$V$46,PER!AT557=1,PER!$V$47,PER!AT597=1,PER!$V$48)))} -> Rez | F6: {=IF(PER!Z56=0,"",IF((PER!AU37+PER!AU77+PER!AU117+PER!AU157+PER!AU197+PER!AU237+PER!AU277+PER!AU317+PER!AU357+PER!AU397+PER!AU437+PER!AU477+PER!AU517+PER!AU557+PER!AU597)=0,"",_xlfn.IFS(PER!AU37=1,PER!$V$34,PER!AU77=1,PER!$V$35,PER!AU117=1,PER!$V$36,PER!AU157=1,PER!$V$37,PER!AU197=1,PER!$V$38,PER!AU237=1,PER!$V$39,PER!AU277=1,PER!$V$40,PER!AU317=1,PER!$V$41,PER!AU357=1,PER!$V$42,PER!AU397=1,PER!$V$43,PER!AU437=1,PER!$V$44,PER!AU477=1,PER!$V$45,PER!AU517=1,PER!$V$46,PER!AU557=1,PER!$V$47,PER!AU597=1,PER!$V$48)))} -> Dummy 1 | G6: {=IF(PER!AA56=0,"",IF((PER!AV37+PER!AV77+PER!AV117+PER!AV157+PER!AV197+PER!AV237+PER!AV277+PER!AV317+PER!AV357+PER!AV397+PER!AV437+PER!AV477+PER!AV517+PER!AV557+PER!AV597)=0,"",_xlfn.IFS(PER!AV37=1,PER!$V$34,PER!AV77=1,PER!$V$35,PER!AV117=1,PER!$V$36,PER!AV157=1,PER!$V$37,PER!AV197=1,PER!$V$38,PER!AV237=1,PER!$V$39,PER!AV277=1,PER!$V$40,PER!AV317=1,PER!$V$41,PER!AV357=1,PER!$V$42,PER!AV397=1,PER!$V$43,PER!AV437=1,PER!$V$44,PER!AV477=1,PER!$V$45,PER!AV517=1,PER!$V$46,PER!AV557=1,PER!$V$47,PER!AV597=1,PER!$V$48)))} -> Level | H6: {=IF(PER!AB56=0,"",IF((PER!AW37+PER!AW77+PER!AW117+PER!AW157+PER!AW197+PER!AW237+PER!AW277+PER!AW317+PER!AW357+PER!AW397+PER!AW437+PER!AW477+PER!AW517+PER!AW557+PER!AW597)=0,"",_xlfn.IFS(PER!AW37=1,PER!$V$34,PER!AW77=1,PER!$V$35,PER!AW117=1,PER!$V$36,PER!AW157=1,PER!$V$37,PER!AW197=1,PER!$V$38,PER!AW237=1,PER!$V$39,PER!AW277=1,PER!$V$40,PER!AW317=1,PER!$V$41,PER!AW357=1,PER!$V$42,PER!AW397=1,PER!$V$43,PER!AW437=1,PER!$V$44,PER!AW477=1,PER!$V$45,PER!AW517=1,PER!$V$46,PER!AW557=1,PER!$V$47,PER!AW597=1,PER!$V$48)))} -> Entry | I6: {=IF(PER!AC56=0,"",IF((PER!AX37+PER!AX77+PER!AX117+PER!AX157+PER!AX197+PER!AX237+PER!AX277+PER!AX317+PER!AX357+PER!AX397+PER!AX437+PER!AX477+PER!AX517+PER!AX557+PER!AX597)=0,"",_xlfn.IFS(PER!AX37=1,PER!$V$34,PER!AX77=1,PER!$V$35,PER!AX117=1,PER!$V$36,PER!AX157=1,PER!$V$37,PER!AX197=1,PER!$V$38,PER!AX237=1,PER!$V$39,PER!AX277=1,PER!$V$40,PER!AX317=1,PER!$V$41,PER!AX357=1,PER!$V$42,PER!AX397=1,PER!$V$43,PER!AX437=1,PER!$V$44,PER!AX477=1,PER!$V$45,PER!AX517=1,PER!$V$46,PER!AX557=1,PER!$V$47,PER!AX597=1,PER!$V$48)))} -> Dummy 4 | J6: {=IF(PER!AD56=0,"",IF((PER!AY37+PER!AY77+PER!AY117+PER!AY157+PER!AY197+PER!AY237+PER!AY277+PER!AY317+PER!AY357+PER!AY397+PER!AY437+PER!AY477+PER!AY517+PER!AY557+PER!AY597)=0,"",_xlfn.IFS(PER!AY37=1,PER!$V$34,PER!AY77=1,PER!$V$35,PER!AY117=1,PER!$V$36,PER!AY157=1,PER!$V$37,PER!AY197=1,PER!$V$38,PER!AY237=1,PER!$V$39,PER!AY277=1,PER!$V$40,PER!AY317=1,PER!$V$41,PER!AY357=1,PER!$V$42,PER!AY397=1,PER!$V$43,PER!AY437=1,PER!$V$44,PER!AY477=1,PER!$V$45,PER!AY517=1,PER!$V$46,PER!AY557=1,PER!$V$47,PER!AY597=1,PER!$V$48)))} -> Entry | ... S6: {=IF(PER!AM56=0,"",IF((PER!BH37+PER!BH77+PER!BH117+PER!BH157+PER!BH197+PER!BH237+PER!BH277+PER!BH317+PER!BH357+PER!BH397+PER!BH437+PER!BH477+PER!BH517+PER!BH557+PER!BH597)=0,"",_xlfn.IFS(PER!BH37=1,PER!$V$34,PER!BH77=1,PER!$V$35,PER!BH117=1,PER!$V$36,PER!BH157=1,PER!$V$37,PER!BH197=1,PER!$V$38,PER!BH237=1,PER!$V$39,PER!BH277=1,PER!$V$40,PER!BH317=1,PER!$V$41,PER!BH357=1,PER!$V$42,PER!BH397=1,PER!$V$43,PER!BH437=1,PER!$V$44,PER!BH477=1,PER!$V$45,PER!BH517=1,PER!$V$46,PER!BH557=1,PER!$V$47,PER!BH597=1,PER!$V$48)))}
A7: 5 | B7: Marcos | C7: {=IF(PER!W57=0,"",IF((PER!AR38+PER!AR78+PER!AR118+PER!AR158+PER!AR198+PER!AR238+PER!AR278+PER!AR318+PER!AR358+PER!AR398+PER!AR438+PER!AR478+PER!AR518+PER!AR558+PER!AR598)=0,"",_xlfn.IFS(PER!AR38=1,PER!$V$34,PER!AR78=1,PER!$V$35,PER!AR118=1,PER!$V$36,PER!AR158=1,PER!$V$37,PER!AR198=1,PER!$V$38,PER!AR238=1,PER!$V$39,PER!AR278=1,PER!$V$40,PER!AR318=1,PER!$V$41,PER!AR358=1,PER!$V$42,PER!AR398=1,PER!$V$43,PER!AR438=1,PER!$V$44,PER!AR478=1,PER!$V$45,PER!AR518=1,PER!$V$46,PER!AR558=1,PER!$V$47,PER!AR598=1,PER!$V$48)))} -> Bar | D7: {=IF(PER!X57=0,"",IF((PER!AS38+PER!AS78+PER!AS118+PER!AS158+PER!AS198+PER!AS238+PER!AS278+PER!AS318+PER!AS358+PER!AS398+PER!AS438+PER!AS478+PER!AS518+PER!AS558+PER!AS598)=0,"",_xlfn.IFS(PER!AS38=1,PER!$V$34,PER!AS78=1,PER!$V$35,PER!AS118=1,PER!$V$36,PER!AS158=1,PER!$V$37,PER!AS198=1,PER!$V$38,PER!AS238=1,PER!$V$39,PER!AS278=1,PER!$V$40,PER!AS318=1,PER!$V$41,PER!AS358=1,PER!$V$42,PER!AS398=1,PER!$V$43,PER!AS438=1,PER!$V$44,PER!AS478=1,PER!$V$45,PER!AS518=1,PER!$V$46,PER!AS558=1,PER!$V$47,PER!AS598=1,PER!$V$48)))} -> C-mix | E7: {=IF(PER!Y57=0,"",IF((PER!AT38+PER!AT78+PER!AT118+PER!AT158+PER!AT198+PER!AT238+PER!AT278+PER!AT318+PER!AT358+PER!AT398+PER!AT438+PER!AT478+PER!AT518+PER!AT558+PER!AT598)=0,"",_xlfn.IFS(PER!AT38=1,PER!$V$34,PER!AT78=1,PER!$V$35,PER!AT118=1,PER!$V$36,PER!AT158=1,PER!$V$37,PER!AT198=1,PER!$V$38,PER!AT238=1,PER!$V$39,PER!AT278=1,PER!$V$40,PER!AT318=1,PER!$V$41,PER!AT358=1,PER!$V$42,PER!AT398=1,PER!$V$43,PER!AT438=1,PER!$V$44,PER!AT478=1,PER!$V$45,PER!AT518=1,PER!$V$46,PER!AT558=1,PER!$V$47,PER!AT598=1,PER!$V$48)))} -> Rez | F7: {=IF(PER!Z57=0,"",IF((PER!AU38+PER!AU78+PER!AU118+PER!AU158+PER!AU198+PER!AU238+PER!AU278+PER!AU318+PER!AU358+PER!AU398+PER!AU438+PER!AU478+PER!AU518+PER!AU558+PER!AU598)=0,"",_xlfn.IFS(PER!AU38=1,PER!$V$34,PER!AU78=1,PER!$V$35,PER!AU118=1,PER!$V$36,PER!AU158=1,PER!$V$37,PER!AU198=1,PER!$V$38,PER!AU238=1,PER!$V$39,PER!AU278=1,PER!$V$40,PER!AU318=1,PER!$V$41,PER!AU358=1,PER!$V$42,PER!AU398=1,PER!$V$43,PER!AU438=1,PER!$V$44,PER!AU478=1,PER!$V$45,PER!AU518=1,PER!$V$46,PER!AU558=1,PER!$V$47,PER!AU598=1,PER!$V$48)))} -> Dummy 1 | G7: {=IF(PER!AA57=0,"",IF((PER!AV38+PER!AV78+PER!AV118+PER!AV158+PER!AV198+PER!AV238+PER!AV278+PER!AV318+PER!AV358+PER!AV398+PER!AV438+PER!AV478+PER!AV518+PER!AV558+PER!AV598)=0,"",_xlfn.IFS(PER!AV38=1,PER!$V$34,PER!AV78=1,PER!$V$35,PER!AV118=1,PER!$V$36,PER!AV158=1,PER!$V$37,PER!AV198=1,PER!$V$38,PER!AV238=1,PER!$V$39,PER!AV278=1,PER!$V$40,PER!AV318=1,PER!$V$41,PER!AV358=1,PER!$V$42,PER!AV398=1,PER!$V$43,PER!AV438=1,PER!$V$44,PER!AV478=1,PER!$V$45,PER!AV518=1,PER!$V$46,PER!AV558=1,PER!$V$47,PER!AV598=1,PER!$V$48)))} -> Rez | H7: {=IF(PER!AB57=0,"",IF((PER!AW38+PER!AW78+PER!AW118+PER!AW158+PER!AW198+PER!AW238+PER!AW278+PER!AW318+PER!AW358+PER!AW398+PER!AW438+PER!AW478+PER!AW518+PER!AW558+PER!AW598)=0,"",_xlfn.IFS(PER!AW38=1,PER!$V$34,PER!AW78=1,PER!$V$35,PER!AW118=1,PER!$V$36,PER!AW158=1,PER!$V$37,PER!AW198=1,PER!$V$38,PER!AW238=1,PER!$V$39,PER!AW278=1,PER!$V$40,PER!AW318=1,PER!$V$41,PER!AW358=1,PER!$V$42,PER!AW398=1,PER!$V$43,PER!AW438=1,PER!$V$44,PER!AW478=1,PER!$V$45,PER!AW518=1,PER!$V$46,PER!AW558=1,PER!$V$47,PER!AW598=1,PER!$V$48)))} -> C-mix | I7: {=IF(PER!AC57=0,"",IF((PER!AX38+PER!AX78+PER!AX118+PER!AX158+PER!AX198+PER!AX238+PER!AX278+PER!AX318+PER!AX358+PER!AX398+PER!AX438+PER!AX478+PER!AX518+PER!AX558+PER!AX598)=0,"",_xlfn.IFS(PER!AX38=1,PER!$V$34,PER!AX78=1,PER!$V$35,PER!AX118=1,PER!$V$36,PER!AX158=1,PER!$V$37,PER!AX198=1,PER!$V$38,PER!AX238=1,PER!$V$39,PER!AX278=1,PER!$V$40,PER!AX318=1,PER!$V$41,PER!AX358=1,PER!$V$42,PER!AX398=1,PER!$V$43,PER!AX438=1,PER!$V$44,PER!AX478=1,PER!$V$45,PER!AX518=1,PER!$V$46,PER!AX558=1,PER!$V$47,PER!AX598=1,PER!$V$48)))} -> Dummy 4 | J7: {=IF(PER!AD57=0,"",IF((PER!AY38+PER!AY78+PER!AY118+PER!AY158+PER!AY198+PER!AY238+PER!AY278+PER!AY318+PER!AY358+PER!AY398+PER!AY438+PER!AY478+PER!AY518+PER!AY558+PER!AY598)=0,"",_xlfn.IFS(PER!AY38=1,PER!$V$34,PER!AY78=1,PER!$V$35,PER!AY118=1,PER!$V$36,PER!AY158=1,PER!$V$37,PER!AY198=1,PER!$V$38,PER!AY238=1,PER!$V$39,PER!AY278=1,PER!$V$40,PER!AY318=1,PER!$V$41,PER!AY358=1,PER!$V$42,PER!AY398=1,PER!$V$43,PER!AY438=1,PER!$V$44,PER!AY478=1,PER!$V$45,PER!AY518=1,PER!$V$46,PER!AY558=1,PER!$V$47,PER!AY598=1,PER!$V$48)))} -> Set up | ... S7: {=IF(PER!AM57=0,"",IF((PER!BH38+PER!BH78+PER!BH118+PER!BH158+PER!BH198+PER!BH238+PER!BH278+PER!BH318+PER!BH358+PER!BH398+PER!BH438+PER!BH478+PER!BH518+PER!BH558+PER!BH598)=0,"",_xlfn.IFS(PER!BH38=1,PER!$V$34,PER!BH78=1,PER!$V$35,PER!BH118=1,PER!$V$36,PER!BH158=1,PER!$V$37,PER!BH198=1,PER!$V$38,PER!BH238=1,PER!$V$39,PER!BH278=1,PER!$V$40,PER!BH318=1,PER!$V$41,PER!BH358=1,PER!$V$42,PER!BH398=1,PER!$V$43,PER!BH438=1,PER!$V$44,PER!BH478=1,PER!$V$45,PER!BH518=1,PER!$V$46,PER!BH558=1,PER!$V$47,PER!BH598=1,PER!$V$48)))}
A8: 6 | B8: Weixin | C8: {=IF(PER!W58=0,"",IF((PER!AR39+PER!AR79+PER!AR119+PER!AR159+PER!AR199+PER!AR239+PER!AR279+PER!AR319+PER!AR359+PER!AR399+PER!AR439+PER!AR479+PER!AR519+PER!AR559+PER!AR599)=0,"",_xlfn.IFS(PER!AR39=1,PER!$V$34,PER!AR79=1,PER!$V$35,PER!AR119=1,PER!$V$36,PER!AR159=1,PER!$V$37,PER!AR199=1,PER!$V$38,PER!AR239=1,PER!$V$39,PER!AR279=1,PER!$V$40,PER!AR319=1,PER!$V$41,PER!AR359=1,PER!$V$42,PER!AR399=1,PER!$V$43,PER!AR439=1,PER!$V$44,PER!AR479=1,PER!$V$45,PER!AR519=1,PER!$V$46,PER!AR559=1,PER!$V$47,PER!AR599=1,PER!$V$48)))} -> Çapèse | D8: {=IF(PER!X58=0,"",IF((PER!AS39+PER!AS79+PER!AS119+PER!AS159+PER!AS199+PER!AS239+PER!AS279+PER!AS319+PER!AS359+PER!AS399+PER!AS439+PER!AS479+PER!AS519+PER!AS559+PER!AS599)=0,"",_xlfn.IFS(PER!AS39=1,PER!$V$34,PER!AS79=1,PER!$V$35,PER!AS119=1,PER!$V$36,PER!AS159=1,PER!$V$37,PER!AS199=1,PER!$V$38,PER!AS239=1,PER!$V$39,PER!AS279=1,PER!$V$40,PER!AS319=1,PER!$V$41,PER!AS359=1,PER!$V$42,PER!AS399=1,PER!$V$43,PER!AS439=1,PER!$V$44,PER!AS479=1,PER!$V$45,PER!AS519=1,PER!$V$46,PER!AS559=1,PER!$V$47,PER!AS599=1,PER!$V$48)))} -> Volante | E8: {=IF(PER!Y58=0,"",IF((PER!AT39+PER!AT79+PER!AT119+PER!AT159+PER!AT199+PER!AT239+PER!AT279+PER!AT319+PER!AT359+PER!AT399+PER!AT439+PER!AT479+PER!AT519+PER!AT559+PER!AT599)=0,"",_xlfn.IFS(PER!AT39=1,PER!$V$34,PER!AT79=1,PER!$V$35,PER!AT119=1,PER!$V$36,PER!AT159=1,PER!$V$37,PER!AT199=1,PER!$V$38,PER!AT239=1,PER!$V$39,PER!AT279=1,PER!$V$40,PER!AT319=1,PER!$V$41,PER!AT359=1,PER!$V$42,PER!AT399=1,PER!$V$43,PER!AT439=1,PER!$V$44,PER!AT479=1,PER!$V$45,PER!AT519=1,PER!$V$46,PER!AT559=1,PER!$V$47,PER!AT599=1,PER!$V$48)))} -> Rez | F8: {=IF(PER!Z58=0,"",IF((PER!AU39+PER!AU79+PER!AU119+PER!AU159+PER!AU199+PER!AU239+PER!AU279+PER!AU319+PER!AU359+PER!AU399+PER!AU439+PER!AU479+PER!AU519+PER!AU559+PER!AU599)=0,"",_xlfn.IFS(PER!AU39=1,PER!$V$34,PER!AU79=1,PER!$V$35,PER!AU119=1,PER!$V$36,PER!AU159=1,PER!$V$37,PER!AU199=1,PER!$V$38,PER!AU239=1,PER!$V$39,PER!AU279=1,PER!$V$40,PER!AU319=1,PER!$V$41,PER!AU359=1,PER!$V$42,PER!AU399=1,PER!$V$43,PER!AU439=1,PER!$V$44,PER!AU479=1,PER!$V$45,PER!AU519=1,PER!$V$46,PER!AU559=1,PER!$V$47,PER!AU599=1,PER!$V$48)))} -> Set up | G8: {=IF(PER!AA58=0,"",IF((PER!AV39+PER!AV79+PER!AV119+PER!AV159+PER!AV199+PER!AV239+PER!AV279+PER!AV319+PER!AV359+PER!AV399+PER!AV439+PER!AV479+PER!AV519+PER!AV559+PER!AV599)=0,"",_xlfn.IFS(PER!AV39=1,PER!$V$34,PER!AV79=1,PER!$V$35,PER!AV119=1,PER!$V$36,PER!AV159=1,PER!$V$37,PER!AV199=1,PER!$V$38,PER!AV239=1,PER!$V$39,PER!AV279=1,PER!$V$40,PER!AV319=1,PER!$V$41,PER!AV359=1,PER!$V$42,PER!AV399=1,PER!$V$43,PER!AV439=1,PER!$V$44,PER!AV479=1,PER!$V$45,PER!AV519=1,PER!$V$46,PER!AV559=1,PER!$V$47,PER!AV599=1,PER!$V$48)))} -> Entry | H8: {=IF(PER!AB58=0,"",IF((PER!AW39+PER!AW79+PER!AW119+PER!AW159+PER!AW199+PER!AW239+PER!AW279+PER!AW319+PER!AW359+PER!AW399+PER!AW439+PER!AW479+PER!AW519+PER!AW559+PER!AW599)=0,"",_xlfn.IFS(PER!AW39=1,PER!$V$34,PER!AW79=1,PER!$V$35,PER!AW119=1,PER!$V$36,PER!AW159=1,PER!$V$37,PER!AW199=1,PER!$V$38,PER!AW239=1,PER!$V$39,PER!AW279=1,PER!$V$40,PER!AW319=1,PER!$V$41,PER!AW359=1,PER!$V$42,PER!AW399=1,PER!$V$43,PER!AW439=1,PER!$V$44,PER!AW479=1,PER!$V$45,PER!AW519=1,PER!$V$46,PER!AW559=1,PER!$V$47,PER!AW599=1,PER!$V$48)))} -> Level | I8: {=IF(PER!AC58=0,"",IF((PER!AX39+PER!AX79+PER!AX119+PER!AX159+PER!AX199+PER!AX239+PER!AX279+PER!AX319+PER!AX359+PER!AX399+PER!AX439+PER!AX479+PER!AX519+PER!AX559+PER!AX599)=0,"",_xlfn.IFS(PER!AX39=1,PER!$V$34,PER!AX79=1,PER!$V$35,PER!AX119=1,PER!$V$36,PER!AX159=1,PER!$V$37,PER!AX199=1,PER!$V$38,PER!AX239=1,PER!$V$39,PER!AX279=1,PER!$V$40,PER!AX319=1,PER!$V$41,PER!AX359=1,PER!$V$42,PER!AX399=1,PER!$V$43,PER!AX439=1,PER!$V$44,PER!AX479=1,PER!$V$45,PER!AX519=1,PER!$V$46,PER!AX559=1,PER!$V$47,PER!AX599=1,PER!$V$48)))} -> Entry | J8: {=IF(PER!AD58=0,"",IF((PER!AY39+PER!AY79+PER!AY119+PER!AY159+PER!AY199+PER!AY239+PER!AY279+PER!AY319+PER!AY359+PER!AY399+PER!AY439+PER!AY479+PER!AY519+PER!AY559+PER!AY599)=0,"",_xlfn.IFS(PER!AY39=1,PER!$V$34,PER!AY79=1,PER!$V$35,PER!AY119=1,PER!$V$36,PER!AY159=1,PER!$V$37,PER!AY199=1,PER!$V$38,PER!AY239=1,PER!$V$39,PER!AY279=1,PER!$V$40,PER!AY319=1,PER!$V$41,PER!AY359=1,PER!$V$42,PER!AY399=1,PER!$V$43,PER!AY439=1,PER!$V$44,PER!AY479=1,PER!$V$45,PER!AY519=1,PER!$V$46,PER!AY559=1,PER!$V$47,PER!AY599=1,PER!$V$48)))} -> Toilets | ... S8: {=IF(PER!AM58=0,"",IF((PER!BH39+PER!BH79+PER!BH119+PER!BH159+PER!BH199+PER!BH239+PER!BH279+PER!BH319+PER!BH359+PER!BH399+PER!BH439+PER!BH479+PER!BH519+PER!BH559+PER!BH599)=0,"",_xlfn.IFS(PER!BH39=1,PER!$V$34,PER!BH79=1,PER!$V$35,PER!BH119=1,PER!$V$36,PER!BH159=1,PER!$V$37,PER!BH199=1,PER!$V$38,PER!BH239=1,PER!$V$39,PER!BH279=1,PER!$V$40,PER!BH319=1,PER!$V$41,PER!BH359=1,PER!$V$42,PER!BH399=1,PER!$V$43,PER!BH439=1,PER!$V$44,PER!BH479=1,PER!$V$45,PER!BH519=1,PER!$V$46,PER!BH559=1,PER!$V$47,PER!BH599=1,PER!$V$48)))}
